Workbook
Name PERFORMANCETASKS: #REF!
Name PT: #REF!
Name QA: #REF!
Name QUARTERLYASSESSMENT: #REF!
Name SUBJECTS: '[1]INPUT DATA'!$A$1002:$A$1005
Name Transmu_Table: #REF!
Name WRITTENWORKS: #REF!
Name WW: #REF!

Sheet INSTRUCTIONS
B2: Exclusively for Strengthened SHS Curriculum Implementers
B3: Instructions: Accomplishing the Electronic Class Record (ECR) for SSHS
C7: 1 | D7: Input the correct data for the following sections. Any details entered here are used throughout the e-Class Record.
E9: This template is intended exclusively for Strengthened SHS Curriculum implementers.
M11: SCHOOL INFO
C12: SCHOOL INFO
C13: 1 | D13: Select the Region where the school is located | K13: → | N13: REGION | S13: :
C14: 2 | D14: Input the respective Schools Division Office | K14: → | N14: DIVISION | S14: :
C16: 3 | D16: Enter the six (6) digit school ID | K16: → | N16: SCHOOL ID | S16: :
C17: 4 | D17: Enter the name of the school | K17: → | N17: SCHOOL NAME | S17: :
C18: 5 | D18: Enter the current school year | K18: → | N18: SCHOOL YEAR | S18: : | T18: 2026 – 2027
D19: Upon donwload of this ECR, the School Year (2026–2027) is already pre-filled. This may be updated.
M21: TEACHER, GRADE LEVEL, AND SUBJECT AREA INFO
C22: TEACHER, GRADE LEVEL, AND SUBJECT AREA INFO
C23: 6 | D23: Enter teacher's name. | K23: → | N23: TEACHER | S23: :
C24: 7 | D24: Input the grade level taught. This field only accepts 11 or 12. | K24: → | N24: GRADE LEVEL | S24: :
C25: 8 | D25: Enter section name. | K25: → | N25: SECTION NAME | S25: :
D26: Indicate "Various Sections" if the class is composed of learners from different sections.
C27: 9 | D27: Select a Subject Category: ACADEMIC, TECH-PRO, or CORE. | K27: → | N27: SUBJECT CATEGORY | S27: :
C28: 10 | D28: Select the appropriate subject cluster. | K28: → | N28: CLUSTER | S28: :
C29: 11 | D29: Select the subject / elective from the dropdown. | K29: → | N29: SUBJECT | S29: :
C30: 12 | D30: If applicable, select “Other Elective and Special Curricular Program”, then enter the new elective or subject in the field provided. Complete the details of the subject in the correct fields. | K30: → | N30: Other Elective & Special Curricular Program / Subject | S30: :
D32: Text highlighted in orange indicates that the selected Track, Cluster, or Subject is not applicable to the grade level. Select only from the available dropdown options. | N32: NO. TERMS TAUGHT | S32: : | V32: Term Blk
N33: UNITS PER TERM | S33: :
C34: 13 | D34: As an additional guide, the number of terms in which the subject is taught (1 or 3), as well as the units to be earned per term and per year, will be displayed once a subject or elective is selected. For Other Electives, manually enter these details in the correct fields. | K34: → | N34: UNITS PER YEAR | S34: :
C37: 14 | D37: For electives offered for one or two terms, indicate the “Term Block.” Data may only be encoded in the sheet corresponding to the selected term. For electives offered for two terms, indicate the first term in which the elective is offered. The succeeding term will automatically be displayed.
D41: A helper notification will display next to the No. of Terms Taught indicating how many Term sheets need to be accomplished.
M42: LEARNERS' NAMES
C44: LEARNERS' NAMES | N44: MALE | T44: FEMALE
C45: 15 | D45: Either manually type the learners' LRNs and names or copy from SF1 and paste onto their respective columns (Male or Female). | K45: → | N45: 1 | O45: LRN | Q45: Name | T45: 1 | U45: LRN | W45: Name
N46: 2 | T46: 2
C47: 16 | D47: Up to 50 learners per group (Male/Female) may be entered. Ensure that the actual class size does not exceed the prescribed maximum class size. | K47: → | N47: 3 | T47: 3
N48: ↓ | T48: ↓
D49: TIPS: | N49: 50 | T49: 50
D50: Press Control + Shift + V to paste values only.
D51: In cases where multiple sections are handled in one class, the corresponding section may be indicated in the row immediately preceding the learners’ names, provided that sufficient rows are available. Color coding may also be used to group learners accordingly.
L52: INSTRUCTIONS | P52: INPUT DATA | U52: Term 1 | W52: Term 2 | Y52: Term 3
C57: 2 | D57: Input the raw scores per Summative Assessment component to compute for the term grades and final grades.
C68: SUMMATIVE ASSESSMENT SCORES | M68: IMPORTANT!
C69: 1 | D69: Select the appropriate sheet for the term (Term 1, Term 2, and/or Term 3).
...

Sheet INPUT DATA
D2: Exclusively for Strengthened SHS Curriculum Implementers
D3: Input Data Sheet for Electronic-Class Record (ECR)
D4: Pursuant to DepEd Order 15, series of 2026
B7: SCHOOL INFO | L7: LEARNERS' NAMES
C10: REGION | E10: : | F10: Region IV-A | N10: LRN | O10: MALE LEARNERS (Last, First Middle) | R10: LRN | S10: FEMALE LEARNERS (Last, First Middle)
C11: DIVISION | E11: : | F11: CALAMBA CITY | M11: 1 | N11: 1234567891 | O11: CALICA, LJAY | Q11: 1
M12: 2 | Q12: 2
C13: SCHOOL ID | E13: : | F13: 301518 | M13: 3 | Q13: 3
C14: SCHOOL NAME | E14: : | F14: EDUARDO BARRETTO SR. INTEGRATED SCHOOL | M14: 4 | Q14: 4
M15: 5 | Q15: 5
C16: SCHOOL YEAR | E16: : | F16: 2026 | G16: =IF(F16>0,"– "&F16+1,"–") -> – 2027 | M16: 6 | Q16: 6
M17: 7 | Q17: 7
M18: 8 | Q18: 8
B19: TEACHER, GRADE LEVEL, AND SUBJECT AREA INFO | M19: 9 | Q19: 9
M20: 10 | Q20: 10
M21: 11 | Q21: 11
C22: TEACHER | E22: : | F22: KAREN P. GONZAGA | M22: 12 | Q22: 12
M23: 13 | Q23: 13
C24: GRADE LEVEL | E24: : | F24: 11 | G24: ← Accepts 11 or 12 only. | M24: 14 | Q24: 14
C25: SECTION NAME | E25: : | F25: MILKY WAY | M25: 15 | Q25: 15
M26: 16 | Q26: 16
C27: STRENGTHENED SHS | M27: 17 | Q27: 17
C28: SUBJECT CATEGORY | E28: : | F28: SSHS - CORE | I28: =_xlfn.IFNA(IF(COUNTIF(INDIRECT(HELPER!$F8),$F28)=0,1,0),0) -> 0 | M28: 18 | Q28: 18
C29: CLUSTER | E29: : | F29: CORE | I29: =_xlfn.IFNA(IF(COUNTIF(INDIRECT(HELPER!$F9),$F29)=0,1,0),0) -> 0 | M29: 19 | Q29: 19
C30: SUBJECT | E30: : | F30: General Mathematics | I30: =_xlfn.IFNA(IF(I29=1,1,IF(COUNTIF(INDIRECT(HELPER!$F10),$F30)=0,1,0)),0) -> 0 | M30: 20 | Q30: 20
M31: 21 | Q31: 21
F32: =IF(COUNTIF(F29,"OTHER*"),"Input the subject in the appropriate field.",IF(SUM(I28:I30)>=1,"Select the correct "&_xlfn.XLOOKUP(1,I28:I30,C28:C30)&".","")) | M32: 22 | Q32: 22
C33: NO. TERMS TAUGHT | E33: : | F33: {=IF(F29<>C37,_xlfn.IFNA(IF($F$24=11,_xlfn.XLOOKUP(1,(HELPER!$I$7:$I$161=1)*(HELPER!$L$7:$L$161='INPUT DATA'!$F$30),HELPER!P$7:P$161),IF($F$24=12,(_xlfn.XLOOKUP(1,(HELPER!$I$7:$I$161=1)*(HELPER!$L$7:$L$161='INPUT DATA'!$F$30),HELPER!T$7:T$161)),"")),""),"")} -> 3 | G33: Term Blk | H33: FIRST TERM | I33: =_xlfn.IFNA(IF(F33="","",IF(F33=3,3,_xlfn.XLOOKUP(H33,HELPER!$G$31:$G$33,HELPER!$F$31:$F$33))),"") -> 3 | M33: 23 | Q33: 23
C34: UNITS PER TERM | E34: : | F34: {=IF(F29<>C37,_xlfn.IFNA(IF($F$24=11,_xlfn.XLOOKUP(1,(HELPER!$I$7:$I$161=1)*(HELPER!$L$7:$L$161='INPUT DATA'!$F$30),HELPER!Q$7:Q$161),IF($F$24=12,(_xlfn.XLOOKUP(1,(HELPER!$I$7:$I$161=1)*(HELPER!$L$7:$L$161='INPUT DATA'!$F$30),HELPER!U$7:U$161)),"")),""),"")} -> 2 | G34: Term Blk | H34: =IFERROR(IF(F33=2,_xlfn.XLOOKUP(I33+1,HELPER!$F$31:$F$34,HELPER!$G$31:$G$34),""),"") | I34: =IF(HELPER!G21=1,(F33&I33)*1,"") -> 33 | M34: 24 | Q34: 24
C35: UNITS PER YEAR | E35: : | F35: {=IF(F29<>C37,_xlfn.IFNA(IF($F$24=11,_xlfn.XLOOKUP(1,(HELPER!$I$7:$I$161=1)*(HELPER!$L$7:$L$161='INPUT DATA'!$F$30),HELPER!R$7:R$161),IF($F$24=12,(_xlfn.XLOOKUP(1,(HELPER!$I$7:$I$161=1)*(HELPER!$L$7:$L$161='INPUT DATA'!$F$30),HELPER!V$7:V$161)),"")),""),"")} -> 6 | G35: =_xlfn.IFNA(_xlfn.XLOOKUP('INPUT DATA'!F33,HELPER!$F$24:$F$26,HELPER!$G$24:$G$26),"") -> Note: Accomplish all Term sheets. | M35: 25 | Q35: 25
M36: 26 | Q36: 26
C37: OTHER ELECTIVE / SPECIAL CURRICULAR PROGRAM | M37: 27 | Q37: 27
C38: =IF(F29=C37,"Input details of the subject below:","") | M38: 28 | Q38: 28
C39: OTHER ELECTIVE | E39: : | M39: 29 | Q39: 29
M40: 30 | Q40: 30
M41: 31 | Q41: 31
C42: COMPONENT WEIGHTS | M42: 32 | Q42: 32
C43: WRITTEN/ORAL WORKS | E43: : | G43: =SUM(F43:F45) -> 0 | M43: 33 | Q43: 33
C44: PERFORMANCE TASKS | E44: : | M44: 34 | Q44: 34
C45: EXAMINATIONS | E45: : | M45: 35 | Q45: 35
...

Sheet Term 1
B2: Strengthened Senior High School Class Record
B3: (Pursuant to DepEd Order 15, series of 2026)
G6: REGION | H6: =UPPER('INPUT DATA'!F10) -> REGION IV-A | O6: DIVISION | P6: =UPPER('INPUT DATA'!F11) -> CALAMBA CITY | Z6: SCHOOL ID | AA6: =IF('INPUT DATA'!F13="","",'INPUT DATA'!F13) -> 301518
G7: SCHOOL NAME | H7: =UPPER('INPUT DATA'!F14) -> EDUARDO BARRETTO SR. INTEGRATED SCHOOL | Z7: SCHOOL YEAR | AA7: ='INPUT DATA'!F16&" "&'INPUT DATA'!G16 -> 2026 – 2027
B8: =IF(OR(HELPER!G23="1ST",HELPER!G23="1ST & 2ND",HELPER!G23="1ST, 2ND, 3RD"),"","INCORRECT SHEET. Do not use this sheet to input data.")
B9: FIRST TERM | D9: GRADE LEVEL | H9: =IFERROR(IF(B8<>"INCORRECT SHEET. Do not use this sheet to input data.",'INPUT DATA'!F24,""),"") -> 11 | J9: SECTION | N9: =IFERROR(IF(B8<>"INCORRECT SHEET. Do not use this sheet to input data.",UPPER('INPUT DATA'!F25),""),"") -> MILKY WAY | Q9: SUBJECT | U9: =IFERROR(IF(B8<>"INCORRECT SHEET. Do not use this sheet to input data.",UPPER(HELPER!G10),""),"") -> GENERAL MATHEMATICS
D10: TEACHER | H10: =IFERROR(IF(B8<>"INCORRECT SHEET. Do not use this sheet to input data.",UPPER('INPUT DATA'!F22),""),"") -> KAREN P. GONZAGA | Q10: CLUSTER | U10: =IFERROR(IF(B8<>"INCORRECT SHEET. Do not use this sheet to input data.",UPPER(HELPER!G9),""),"") -> CORE | AH10: UNITS | AJ10: =IFERROR(IF(B8<>"INCORRECT SHEET. Do not use this sheet to input data.",HELPER!G27,""),"") -> 2 | AK10: / TERM | AL10: =IFERROR(IF(B8<>"INCORRECT SHEET. Do not use this sheet to input data.",HELPER!G28,""),"") -> 6 | AM10: / YEAR
D11: WRITTEN / ORAL WORKS (WWs) | Q11: PRODUCT / PERFORMANCE TASKS (PTs) | AD11: EXAMINATIONS (EXs) | AL11: INITIAL GRADE | AM11: TERM GRADE
D12: =IF($U$9<>"",IFERROR(_xlfn.IFNA(HELPER!G13/100,""),""),"") -> 0.2 | Q12: =IF($U$9<>"",IFERROR(_xlfn.IFNA(HELPER!G14/100,""),""),"") -> 0.5 | AD12: =IF($U$9<>"",IFERROR(_xlfn.IFNA(HELPER!G15/100,""),""),"") -> 0.3
D13: 1 | E13: 2 | F13: 3 | G13: 4 | H13: 5 | I13: 6 | J13: 7 | K13: 8 | L13: 9 | M13: 10 | N13: TOTAL | O13: PS | P13: WS | Q13: 1 | R13: 2 | S13: 3 | T13: 4 | U13: 5 | V13: 6 | W13: 7 | X13: 8 | Y13: 9 | Z13: 10 | AA13: TOTAL | AB13: PS | AC13: WS | AD13: ST 1 | AE13: ST 2 | AF13: TE | AG13: WS ST1 | AH13: WS ST2 | AI13: WS TE | AJ13: PS | AK13: WS
B14: HIGHEST POSSIBLE SCORE | D14: 50 | E14: 10 | F14: 1 | G14: 1 | N14: =SUM(D14:M14) -> 62 | O14: 100 | P14: =D12 -> 0.2 | Q14: 50 | R14: 12 | AA14: =SUM(Q14:Z14) -> 62 | AB14: 100 | AC14: =Q12 -> 0.5 | AD14: 50 | AE14: 50 | AF14: 50 | AG14: =_xlfn.IFNA(HELPER!G17,"") -> 30 | AH14: =_xlfn.IFNA(HELPER!G18,"") -> 30 | AI14: =_xlfn.IFNA(HELPER!G19,"") -> 40 | AJ14: =IF(AD12=0,"",100) -> 100 | AK14: =AD12 -> 0.3
B15: LEARNERS' NAMES
B16: MALE
B17: 1 | C17: =IFERROR(IF(OR($B$8="INCORRECT SHEET. Do not use this sheet to input data.",'INPUT DATA'!O11=""),"",'INPUT DATA'!O11),"") -> CALICA, LJAY | D17: 49 | E17: 10 | F17: 1 | G17: 1 | N17: =IF(COUNT(D17:M17)=0,"",SUM(D17:M17)) -> 61 | O17: =IFERROR(IF(N17="","",ROUND(N17/N$14*O$14,2)),"") -> 98.39 | P17: =IFERROR(IF(O17="","",ROUND(O17*P$14,2)),"") -> 19.68 | Q17: 29 | R17: 12 | AA17: =IF(COUNT(Q17:Z17)=0,"",SUM(Q17:Z17)) -> 41 | AB17: =IFERROR(IF(AA17="","",ROUND(AA17/AA$14*AB$14,2)),"") -> 66.13 | AC17: =IFERROR(IF(AB17="","",ROUND(AB17*AC$14,2)),"") -> 33.07 | AD17: 50 | AE17: 49 | AF17: 44 | AG17: =IFERROR(IF(AD17="","",ROUND(AD17/$AD$14*$AG$14,2)),"") -> 30 | AH17: =IFERROR(IF(AE17="","",ROUND(AE17/$AE$14*$AH$14,2)),"") -> 29.4 | AI17: =IFERROR(IF(AF17="","",ROUND(AF17/$AF$14*$AI$14,2)),"") -> 35.2 | AJ17: =IF($AD$12=0,"",IF(OR(AG17<>"",AH17<>"",AI17<>""),(SUM(AG17:AI17)/SUM($AG$14:$AI$14))*$AJ$14,"")) -> 94.6 | AK17: =IFERROR(IF(AJ17="","",ROUND(AJ17*$AK$14,2)),"") -> 28.38 | AL17: =IF(AND(C17<>"",P17<>"",AC17<>"",$AD$12=0),SUM(P17,AC17),IF(AND(C17<>"",P17<>"",AC17<>"",AK17<>"",$D$12>0,$Q$12>0,$AD$12>0),SUM(P17,AC17,AK17),"")) -> 81.13 | AM17: =IFERROR(_xlfn.XLOOKUP(AL17,HELPER!$C$7:$C$47,HELPER!$D$7:$D$47,,1),"") -> 84
B18: 2 | C18: =IFERROR(IF(OR($B$8="INCORRECT SHEET. Do not use this sheet to input data.",'INPUT DATA'!O12=""),"",'INPUT DATA'!O12),"") | N18: =IF(COUNT(D18:M18)=0,"",SUM(D18:M18)) | O18: =IFERROR(IF(N18="","",ROUND(N18/N$14*O$14,2)),"") | P18: =IFERROR(IF(O18="","",ROUND(O18*P$14,2)),"") | AA18: =IF(COUNT(Q18:Z18)=0,"",SUM(Q18:Z18)) | AB18: =IFERROR(IF(AA18="","",ROUND(AA18/AA$14*AB$14,2)),"") | AC18: =IFERROR(IF(AB18="","",ROUND(AB18*AC$14,2)),"") | AG18: =IFERROR(IF(AD18="","",ROUND(AD18/$AD$14*$AG$14,2)),"") | AH18: =IFERROR(IF(AE18="","",ROUND(AE18/$AE$14*$AH$14,2)),"") | AI18: =IFERROR(IF(AF18="","",ROUND(AF18/$AF$14*$AI$14,2)),"") | AJ18: =IF($AD$12=0,"",IF(OR(AG18<>"",AH18<>"",AI18<>""),(SUM(AG18:AI18)/SUM($AG$14:$AI$14))*$AJ$14,"")) | AK18: =IFERROR(IF(AJ18="","",ROUND(AJ18*$AK$14,2)),"") | AL18: =IF(AND(C18<>"",P18<>"",AC18<>"",$AD$12=0),SUM(P18,AC18),IF(AND(C18<>"",P18<>"",AC18<>"",AK18<>"",$D$12>0,$Q$12>0,$AD$12>0),SUM(P18,AC18,AK18),"")) | AM18: =IFERROR(_xlfn.XLOOKUP(AL18,HELPER!$C$7:$C$47,HELPER!$D$7:$D$47,,1),"")
B19: 3 | C19: =IFERROR(IF(OR($B$8="INCORRECT SHEET. Do not use this sheet to input data.",'INPUT DATA'!O13=""),"",'INPUT DATA'!O13),"") | N19: =IF(COUNT(D19:M19)=0,"",SUM(D19:M19)) | O19: =IFERROR(IF(N19="","",ROUND(N19/N$14*O$14,2)),"") | P19: =IFERROR(IF(O19="","",ROUND(O19*P$14,2)),"") | AA19: =IF(COUNT(Q19:Z19)=0,"",SUM(Q19:Z19)) | AB19: =IFERROR(IF(AA19="","",ROUND(AA19/AA$14*AB$14,2)),"") | AC19: =IFERROR(IF(AB19="","",ROUND(AB19*AC$14,2)),"") | AG19: =IFERROR(IF(AD19="","",ROUND(AD19/$AD$14*$AG$14,2)),"") | AH19: =IFERROR(IF(AE19="","",ROUND(AE19/$AE$14*$AH$14,2)),"") | AI19: =IFERROR(IF(AF19="","",ROUND(AF19/$AF$14*$AI$14,2)),"") | AJ19: =IF($AD$12=0,"",IF(OR(AG19<>"",AH19<>"",AI19<>""),(SUM(AG19:AI19)/SUM($AG$14:$AI$14))*$AJ$14,"")) | AK19: =IFERROR(IF(AJ19="","",ROUND(AJ19*$AK$14,2)),"") | AL19: =IF(AND(C19<>"",P19<>"",AC19<>"",$AD$12=0),SUM(P19,AC19),IF(AND(C19<>"",P19<>"",AC19<>"",AK19<>"",$D$12>0,$Q$12>0,$AD$12>0),SUM(P19,AC19,AK19),"")) | AM19: =IFERROR(_xlfn.XLOOKUP(AL19,HELPER!$C$7:$C$47,HELPER!$D$7:$D$47,,1),"")
B20: 4 | C20: =IFERROR(IF(OR($B$8="INCORRECT SHEET. Do not use this sheet to input data.",'INPUT DATA'!O14=""),"",'INPUT DATA'!O14),"") | N20: =IF(COUNT(D20:M20)=0,"",SUM(D20:M20)) | O20: =IFERROR(IF(N20="","",ROUND(N20/N$14*O$14,2)),"") | P20: =IFERROR(IF(O20="","",ROUND(O20*P$14,2)),"") | AA20: =IF(COUNT(Q20:Z20)=0,"",SUM(Q20:Z20)) | AB20: =IFERROR(IF(AA20="","",ROUND(AA20/AA$14*AB$14,2)),"") | AC20: =IFERROR(IF(AB20="","",ROUND(AB20*AC$14,2)),"") | AG20: =IFERROR(IF(AD20="","",ROUND(AD20/$AD$14*$AG$14,2)),"") | AH20: =IFERROR(IF(AE20="","",ROUND(AE20/$AE$14*$AH$14,2)),"") | AI20: =IFERROR(IF(AF20="","",ROUND(AF20/$AF$14*$AI$14,2)),"") | AJ20: =IF($AD$12=0,"",IF(OR(AG20<>"",AH20<>"",AI20<>""),(SUM(AG20:AI20)/SUM($AG$14:$AI$14))*$AJ$14,"")) | AK20: =IFERROR(IF(AJ20="","",ROUND(AJ20*$AK$14,2)),"") | AL20: =IF(AND(C20<>"",P20<>"",AC20<>"",$AD$12=0),SUM(P20,AC20),IF(AND(C20<>"",P20<>"",AC20<>"",AK20<>"",$D$12>0,$Q$12>0,$AD$12>0),SUM(P20,AC20,AK20),"")) | AM20: =IFERROR(_xlfn.XLOOKUP(AL20,HELPER!$C$7:$C$47,HELPER!$D$7:$D$47,,1),"")
B21: 5 | C21: =IFERROR(IF(OR($B$8="INCORRECT SHEET. Do not use this sheet to input data.",'INPUT DATA'!O15=""),"",'INPUT DATA'!O15),"") | N21: =IF(COUNT(D21:M21)=0,"",SUM(D21:M21)) | O21: =IFERROR(IF(N21="","",ROUND(N21/N$14*O$14,2)),"") | P21: =IFERROR(IF(O21="","",ROUND(O21*P$14,2)),"") | AA21: =IF(COUNT(Q21:Z21)=0,"",SUM(Q21:Z21)) | AB21: =IFERROR(IF(AA21="","",ROUND(AA21/AA$14*AB$14,2)),"") | AC21: =IFERROR(IF(AB21="","",ROUND(AB21*AC$14,2)),"") | AG21: =IFERROR(IF(AD21="","",ROUND(AD21/$AD$14*$AG$14,2)),"") | AH21: =IFERROR(IF(AE21="","",ROUND(AE21/$AE$14*$AH$14,2)),"") | AI21: =IFERROR(IF(AF21="","",ROUND(AF21/$AF$14*$AI$14,2)),"") | AJ21: =IF($AD$12=0,"",IF(OR(AG21<>"",AH21<>"",AI21<>""),(SUM(AG21:AI21)/SUM($AG$14:$AI$14))*$AJ$14,"")) | AK21: =IFERROR(IF(AJ21="","",ROUND(AJ21*$AK$14,2)),"") | AL21: =IF(AND(C21<>"",P21<>"",AC21<>"",$AD$12=0),SUM(P21,AC21),IF(AND(C21<>"",P21<>"",AC21<>"",AK21<>"",$D$12>0,$Q$12>0,$AD$12>0),SUM(P21,AC21,AK21),"")) | AM21: =IFERROR(_xlfn.XLOOKUP(AL21,HELPER!$C$7:$C$47,HELPER!$D$7:$D$47,,1),"")
B22: 6 | C22: =IFERROR(IF(OR($B$8="INCORRECT SHEET. Do not use this sheet to input data.",'INPUT DATA'!O16=""),"",'INPUT DATA'!O16),"") | N22: =IF(COUNT(D22:M22)=0,"",SUM(D22:M22)) | O22: =IFERROR(IF(N22="","",ROUND(N22/N$14*O$14,2)),"") | P22: =IFERROR(IF(O22="","",ROUND(O22*P$14,2)),"") | AA22: =IF(COUNT(Q22:Z22)=0,"",SUM(Q22:Z22)) | AB22: =IFERROR(IF(AA22="","",ROUND(AA22/AA$14*AB$14,2)),"") | AC22: =IFERROR(IF(AB22="","",ROUND(AB22*AC$14,2)),"") | AG22: =IFERROR(IF(AD22="","",ROUND(AD22/$AD$14*$AG$14,2)),"") | AH22: =IFERROR(IF(AE22="","",ROUND(AE22/$AE$14*$AH$14,2)),"") | AI22: =IFERROR(IF(AF22="","",ROUND(AF22/$AF$14*$AI$14,2)),"") | AJ22: =IF($AD$12=0,"",IF(OR(AG22<>"",AH22<>"",AI22<>""),(SUM(AG22:AI22)/SUM($AG$14:$AI$14))*$AJ$14,"")) | AK22: =IFERROR(IF(AJ22="","",ROUND(AJ22*$AK$14,2)),"") | AL22: =IF(AND(C22<>"",P22<>"",AC22<>"",$AD$12=0),SUM(P22,AC22),IF(AND(C22<>"",P22<>"",AC22<>"",AK22<>"",$D$12>0,$Q$12>0,$AD$12>0),SUM(P22,AC22,AK22),"")) | AM22: =IFERROR(_xlfn.XLOOKUP(AL22,HELPER!$C$7:$C$47,HELPER!$D$7:$D$47,,1),"")
B23: 7 | C23: =IFERROR(IF(OR($B$8="INCORRECT SHEET. Do not use this sheet to input data.",'INPUT DATA'!O17=""),"",'INPUT DATA'!O17),"") | N23: =IF(COUNT(D23:M23)=0,"",SUM(D23:M23)) | O23: =IFERROR(IF(N23="","",ROUND(N23/N$14*O$14,2)),"") | P23: =IFERROR(IF(O23="","",ROUND(O23*P$14,2)),"") | AA23: =IF(COUNT(Q23:Z23)=0,"",SUM(Q23:Z23)) | AB23: =IFERROR(IF(AA23="","",ROUND(AA23/AA$14*AB$14,2)),"") | AC23: =IFERROR(IF(AB23="","",ROUND(AB23*AC$14,2)),"") | AG23: =IFERROR(IF(AD23="","",ROUND(AD23/$AD$14*$AG$14,2)),"") | AH23: =IFERROR(IF(AE23="","",ROUND(AE23/$AE$14*$AH$14,2)),"") | AI23: =IFERROR(IF(AF23="","",ROUND(AF23/$AF$14*$AI$14,2)),"") | AJ23: =IF($AD$12=0,"",IF(OR(AG23<>"",AH23<>"",AI23<>""),(SUM(AG23:AI23)/SUM($AG$14:$AI$14))*$AJ$14,"")) | AK23: =IFERROR(IF(AJ23="","",ROUND(AJ23*$AK$14,2)),"") | AL23: =IF(AND(C23<>"",P23<>"",AC23<>"",$AD$12=0),SUM(P23,AC23),IF(AND(C23<>"",P23<>"",AC23<>"",AK23<>"",$D$12>0,$Q$12>0,$AD$12>0),SUM(P23,AC23,AK23),"")) | AM23: =IFERROR(_xlfn.XLOOKUP(AL23,HELPER!$C$7:$C$47,HELPER!$D$7:$D$47,,1),"")
B24: 8 | C24: =IFERROR(IF(OR($B$8="INCORRECT SHEET. Do not use this sheet to input data.",'INPUT DATA'!O18=""),"",'INPUT DATA'!O18),"") | N24: =IF(COUNT(D24:M24)=0,"",SUM(D24:M24)) | O24: =IFERROR(IF(N24="","",ROUND(N24/N$14*O$14,2)),"") | P24: =IFERROR(IF(O24="","",ROUND(O24*P$14,2)),"") | AA24: =IF(COUNT(Q24:Z24)=0,"",SUM(Q24:Z24)) | AB24: =IFERROR(IF(AA24="","",ROUND(AA24/AA$14*AB$14,2)),"") | AC24: =IFERROR(IF(AB24="","",ROUND(AB24*AC$14,2)),"") | AG24: =IFERROR(IF(AD24="","",ROUND(AD24/$AD$14*$AG$14,2)),"") | AH24: =IFERROR(IF(AE24="","",ROUND(AE24/$AE$14*$AH$14,2)),"") | AI24: =IFERROR(IF(AF24="","",ROUND(AF24/$AF$14*$AI$14,2)),"") | AJ24: =IF($AD$12=0,"",IF(OR(AG24<>"",AH24<>"",AI24<>""),(SUM(AG24:AI24)/SUM($AG$14:$AI$14))*$AJ$14,"")) | AK24: =IFERROR(IF(AJ24="","",ROUND(AJ24*$AK$14,2)),"") | AL24: =IF(AND(C24<>"",P24<>"",AC24<>"",$AD$12=0),SUM(P24,AC24),IF(AND(C24<>"",P24<>"",AC24<>"",AK24<>"",$D$12>0,$Q$12>0,$AD$12>0),SUM(P24,AC24,AK24),"")) | AM24: =IFERROR(_xlfn.XLOOKUP(AL24,HELPER!$C$7:$C$47,HELPER!$D$7:$D$47,,1),"")
B25: 9 | C25: =IFERROR(IF(OR($B$8="INCORRECT SHEET. Do not use this sheet to input data.",'INPUT DATA'!O19=""),"",'INPUT DATA'!O19),"") | N25: =IF(COUNT(D25:M25)=0,"",SUM(D25:M25)) | O25: =IFERROR(IF(N25="","",ROUND(N25/N$14*O$14,2)),"") | P25: =IFERROR(IF(O25="","",ROUND(O25*P$14,2)),"") | AA25: =IF(COUNT(Q25:Z25)=0,"",SUM(Q25:Z25)) | AB25: =IFERROR(IF(AA25="","",ROUND(AA25/AA$14*AB$14,2)),"") | AC25: =IFERROR(IF(AB25="","",ROUND(AB25*AC$14,2)),"") | AG25: =IFERROR(IF(AD25="","",ROUND(AD25/$AD$14*$AG$14,2)),"") | AH25: =IFERROR(IF(AE25="","",ROUND(AE25/$AE$14*$AH$14,2)),"") | AI25: =IFERROR(IF(AF25="","",ROUND(AF25/$AF$14*$AI$14,2)),"") | AJ25: =IF($AD$12=0,"",IF(OR(AG25<>"",AH25<>"",AI25<>""),(SUM(AG25:AI25)/SUM($AG$14:$AI$14))*$AJ$14,"")) | AK25: =IFERROR(IF(AJ25="","",ROUND(AJ25*$AK$14,2)),"") | AL25: =IF(AND(C25<>"",P25<>"",AC25<>"",$AD$12=0),SUM(P25,AC25),IF(AND(C25<>"",P25<>"",AC25<>"",AK25<>"",$D$12>0,$Q$12>0,$AD$12>0),SUM(P25,AC25,AK25),"")) | AM25: =IFERROR(_xlfn.XLOOKUP(AL25,HELPER!$C$7:$C$47,HELPER!$D$7:$D$47,,1),"")
B26: 10 | C26: =IFERROR(IF(OR($B$8="INCORRECT SHEET. Do not use this sheet to input data.",'INPUT DATA'!O20=""),"",'INPUT DATA'!O20),"") | N26: =IF(COUNT(D26:M26)=0,"",SUM(D26:M26)) | O26: =IFERROR(IF(N26="","",ROUND(N26/N$14*O$14,2)),"") | P26: =IFERROR(IF(O26="","",ROUND(O26*P$14,2)),"") | AA26: =IF(COUNT(Q26:Z26)=0,"",SUM(Q26:Z26)) | AB26: =IFERROR(IF(AA26="","",ROUND(AA26/AA$14*AB$14,2)),"") | AC26: =IFERROR(IF(AB26="","",ROUND(AB26*AC$14,2)),"") | AG26: =IFERROR(IF(AD26="","",ROUND(AD26/$AD$14*$AG$14,2)),"") | AH26: =IFERROR(IF(AE26="","",ROUND(AE26/$AE$14*$AH$14,2)),"") | AI26: =IFERROR(IF(AF26="","",ROUND(AF26/$AF$14*$AI$14,2)),"") | AJ26: =IF($AD$12=0,"",IF(OR(AG26<>"",AH26<>"",AI26<>""),(SUM(AG26:AI26)/SUM($AG$14:$AI$14))*$AJ$14,"")) | AK26: =IFERROR(IF(AJ26="","",ROUND(AJ26*$AK$14,2)),"") | AL26: =IF(AND(C26<>"",P26<>"",AC26<>"",$AD$12=0),SUM(P26,AC26),IF(AND(C26<>"",P26<>"",AC26<>"",AK26<>"",$D$12>0,$Q$12>0,$AD$12>0),SUM(P26,AC26,AK26),"")) | AM26: =IFERROR(_xlfn.XLOOKUP(AL26,HELPER!$C$7:$C$47,HELPER!$D$7:$D$47,,1),"")
B27: 11 | C27: =IFERROR(IF(OR($B$8="INCORRECT SHEET. Do not use this sheet to input data.",'INPUT DATA'!O21=""),"",'INPUT DATA'!O21),"") | N27: =IF(COUNT(D27:M27)=0,"",SUM(D27:M27)) | O27: =IFERROR(IF(N27="","",ROUND(N27/N$14*O$14,2)),"") | P27: =IFERROR(IF(O27="","",ROUND(O27*P$14,2)),"") | AA27: =IF(COUNT(Q27:Z27)=0,"",SUM(Q27:Z27)) | AB27: =IFERROR(IF(AA27="","",ROUND(AA27/AA$14*AB$14,2)),"") | AC27: =IFERROR(IF(AB27="","",ROUND(AB27*AC$14,2)),"") | AG27: =IFERROR(IF(AD27="","",ROUND(AD27/$AD$14*$AG$14,2)),"") | AH27: =IFERROR(IF(AE27="","",ROUND(AE27/$AE$14*$AH$14,2)),"") | AI27: =IFERROR(IF(AF27="","",ROUND(AF27/$AF$14*$AI$14,2)),"") | AJ27: =IF($AD$12=0,"",IF(OR(AG27<>"",AH27<>"",AI27<>""),(SUM(AG27:AI27)/SUM($AG$14:$AI$14))*$AJ$14,"")) | AK27: =IFERROR(IF(AJ27="","",ROUND(AJ27*$AK$14,2)),"") | AL27: =IF(AND(C27<>"",P27<>"",AC27<>"",$AD$12=0),SUM(P27,AC27),IF(AND(C27<>"",P27<>"",AC27<>"",AK27<>"",$D$12>0,$Q$12>0,$AD$12>0),SUM(P27,AC27,AK27),"")) | AM27: =IFERROR(_xlfn.XLOOKUP(AL27,HELPER!$C$7:$C$47,HELPER!$D$7:$D$47,,1),"")
B28: 12 | C28: =IFERROR(IF(OR($B$8="INCORRECT SHEET. Do not use this sheet to input data.",'INPUT DATA'!O22=""),"",'INPUT DATA'!O22),"") | N28: =IF(COUNT(D28:M28)=0,"",SUM(D28:M28)) | O28: =IFERROR(IF(N28="","",ROUND(N28/N$14*O$14,2)),"") | P28: =IFERROR(IF(O28="","",ROUND(O28*P$14,2)),"") | AA28: =IF(COUNT(Q28:Z28)=0,"",SUM(Q28:Z28)) | AB28: =IFERROR(IF(AA28="","",ROUND(AA28/AA$14*AB$14,2)),"") | AC28: =IFERROR(IF(AB28="","",ROUND(AB28*AC$14,2)),"") | AG28: =IFERROR(IF(AD28="","",ROUND(AD28/$AD$14*$AG$14,2)),"") | AH28: =IFERROR(IF(AE28="","",ROUND(AE28/$AE$14*$AH$14,2)),"") | AI28: =IFERROR(IF(AF28="","",ROUND(AF28/$AF$14*$AI$14,2)),"") | AJ28: =IF($AD$12=0,"",IF(OR(AG28<>"",AH28<>"",AI28<>""),(SUM(AG28:AI28)/SUM($AG$14:$AI$14))*$AJ$14,"")) | AK28: =IFERROR(IF(AJ28="","",ROUND(AJ28*$AK$14,2)),"") | AL28: =IF(AND(C28<>"",P28<>"",AC28<>"",$AD$12=0),SUM(P28,AC28),IF(AND(C28<>"",P28<>"",AC28<>"",AK28<>"",$D$12>0,$Q$12>0,$AD$12>0),SUM(P28,AC28,AK28),"")) | AM28: =IFERROR(_xlfn.XLOOKUP(AL28,HELPER!$C$7:$C$47,HELPER!$D$7:$D$47,,1),"")
B29: 13 | C29: =IFERROR(IF(OR($B$8="INCORRECT SHEET. Do not use this sheet to input data.",'INPUT DATA'!O23=""),"",'INPUT DATA'!O23),"") | N29: =IF(COUNT(D29:M29)=0,"",SUM(D29:M29)) | O29: =IFERROR(IF(N29="","",ROUND(N29/N$14*O$14,2)),"") | P29: =IFERROR(IF(O29="","",ROUND(O29*P$14,2)),"") | AA29: =IF(COUNT(Q29:Z29)=0,"",SUM(Q29:Z29)) | AB29: =IFERROR(IF(AA29="","",ROUND(AA29/AA$14*AB$14,2)),"") | AC29: =IFERROR(IF(AB29="","",ROUND(AB29*AC$14,2)),"") | AG29: =IFERROR(IF(AD29="","",ROUND(AD29/$AD$14*$AG$14,2)),"") | AH29: =IFERROR(IF(AE29="","",ROUND(AE29/$AE$14*$AH$14,2)),"") | AI29: =IFERROR(IF(AF29="","",ROUND(AF29/$AF$14*$AI$14,2)),"") | AJ29: =IF($AD$12=0,"",IF(OR(AG29<>"",AH29<>"",AI29<>""),(SUM(AG29:AI29)/SUM($AG$14:$AI$14))*$AJ$14,"")) | AK29: =IFERROR(IF(AJ29="","",ROUND(AJ29*$AK$14,2)),"") | AL29: =IF(AND(C29<>"",P29<>"",AC29<>"",$AD$12=0),SUM(P29,AC29),IF(AND(C29<>"",P29<>"",AC29<>"",AK29<>"",$D$12>0,$Q$12>0,$AD$12>0),SUM(P29,AC29,AK29),"")) | AM29: =IFERROR(_xlfn.XLOOKUP(AL29,HELPER!$C$7:$C$47,HELPER!$D$7:$D$47,,1),"")
... B66: 50 | C66: =IFERROR(IF(OR($B$8="INCORRECT SHEET. Do not use this sheet to input data.",'INPUT DATA'!O60=""),"",'INPUT DATA'!O60),"") | N66: =IF(COUNT(D66:M66)=0,"",SUM(D66:M66)) | O66: =IFERROR(IF(N66="","",ROUND(N66/N$14*O$14,2)),"") | P66: =IFERROR(IF(O66="","",ROUND(O66*P$14,2)),"") | AA66: =IF(COUNT(Q66:Z66)=0,"",SUM(Q66:Z66)) | AB66: =IFERROR(IF(AA66="","",ROUND(AA66/AA$14*AB$14,2)),"") | AC66: =IFERROR(IF(AB66="","",ROUND(AB66*AC$14,2)),"") | AG66: =IFERROR(IF(AD66="","",ROUND(AD66/$AD$14*$AG$14,2)),"") | AH66: =IFERROR(IF(AE66="","",ROUND(AE66/$AE$14*$AH$14,2)),"") | AI66: =IFERROR(IF(AF66="","",ROUND(AF66/$AF$14*$AI$14,2)),"") | AJ66: =IF($AD$12=0,"",IF(OR(AG66<>"",AH66<>"",AI66<>""),(SUM(AG66:AI66)/SUM($AG$14:$AI$14))*$AJ$14,"")) | AK66: =IFERROR(IF(AJ66="","",ROUND(AJ66*$AK$14,2)),"") | AL66: =IF(AND(C66<>"",P66<>"",AC66<>"",$AD$12=0),SUM(P66,AC66),IF(AND(C66<>"",P66<>"",AC66<>"",AK66<>"",$D$12>0,$Q$12>0,$AD$12>0),SUM(P66,AC66,AK66),"")) | AM66: =IFERROR(_xlfn.XLOOKUP(AL66,HELPER!$C$7:$C$47,HELPER!$D$7:$D$47,,1),"")
B67: FEMALE
B68: 1 | C68: =IFERROR(IF(OR($B$8="INCORRECT SHEET. Do not use this sheet to input data.",'INPUT DATA'!S11=""),"",'INPUT DATA'!S11),"") | N68: =IF(COUNT(D68:M68)=0,"",SUM(D68:M68)) | O68: =IFERROR(IF(N68="","",ROUND(N68/N$14*O$14,2)),"") | P68: =IFERROR(IF(O68="","",ROUND(O68*P$14,2)),"") | AA68: =IF(COUNT(Q68:Z68)=0,"",SUM(Q68:Z68)) | AB68: =IFERROR(IF(AA68="","",ROUND(AA68/AA$14*AB$14,2)),"") | AC68: =IFERROR(IF(AB68="","",ROUND(AB68*AC$14,2)),"") | AG68: =IFERROR(IF(AD68="","",ROUND(AD68/$AD$14*$AG$14,2)),"") | AH68: =IFERROR(IF(AE68="","",ROUND(AE68/$AE$14*$AH$14,2)),"") | AI68: =IFERROR(IF(AF68="","",ROUND(AF68/$AF$14*$AI$14,2)),"") | AJ68: =IF($AD$12=0,"",IF(OR(AG68<>"",AH68<>"",AI68<>""),(SUM(AG68:AI68)/SUM($AG$14:$AI$14))*$AJ$14,"")) | AK68: =IFERROR(IF(AJ68="","",ROUND(AJ68*$AK$14,2)),"") | AL68: =IF(AND(C68<>"",P68<>"",AC68<>"",$AD$12=0),SUM(P68,AC68),IF(AND(C68<>"",P68<>"",AC68<>"",AK68<>"",$D$12>0,$Q$12>0,$AD$12>0),SUM(P68,AC68,AK68),"")) | AM68: =IFERROR(_xlfn.XLOOKUP(AL68,HELPER!$C$7:$C$47,HELPER!$D$7:$D$47,,1),"")
B69: 2 | C69: =IFERROR(IF(OR($B$8="INCORRECT SHEET. Do not use this sheet to input data.",'INPUT DATA'!S12=""),"",'INPUT DATA'!S12),"") | N69: =IF(COUNT(D69:M69)=0,"",SUM(D69:M69)) | O69: =IFERROR(IF(N69="","",ROUND(N69/N$14*O$14,2)),"") | P69: =IFERROR(IF(O69="","",ROUND(O69*P$14,2)),"") | AA69: =IF(COUNT(Q69:Z69)=0,"",SUM(Q69:Z69)) | AB69: =IFERROR(IF(AA69="","",ROUND(AA69/AA$14*AB$14,2)),"") | AC69: =IFERROR(IF(AB69="","",ROUND(AB69*AC$14,2)),"") | AG69: =IFERROR(IF(AD69="","",ROUND(AD69/$AD$14*$AG$14,2)),"") | AH69: =IFERROR(IF(AE69="","",ROUND(AE69/$AE$14*$AH$14,2)),"") | AI69: =IFERROR(IF(AF69="","",ROUND(AF69/$AF$14*$AI$14,2)),"") | AJ69: =IF($AD$12=0,"",IF(OR(AG69<>"",AH69<>"",AI69<>""),(SUM(AG69:AI69)/SUM($AG$14:$AI$14))*$AJ$14,"")) | AK69: =IFERROR(IF(AJ69="","",ROUND(AJ69*$AK$14,2)),"") | AL69: =IF(AND(C69<>"",P69<>"",AC69<>"",$AD$12=0),SUM(P69,AC69),IF(AND(C69<>"",P69<>"",AC69<>"",AK69<>"",$D$12>0,$Q$12>0,$AD$12>0),SUM(P69,AC69,AK69),"")) | AM69: =IFERROR(_xlfn.XLOOKUP(AL69,HELPER!$C$7:$C$47,HELPER!$D$7:$D$47,,1),"")
B70: 3 | C70: =IFERROR(IF(OR($B$8="INCORRECT SHEET. Do not use this sheet to input data.",'INPUT DATA'!S13=""),"",'INPUT DATA'!S13),"") | N70: =IF(COUNT(D70:M70)=0,"",SUM(D70:M70)) | O70: =IFERROR(IF(N70="","",ROUND(N70/N$14*O$14,2)),"") | P70: =IFERROR(IF(O70="","",ROUND(O70*P$14,2)),"") | AA70: =IF(COUNT(Q70:Z70)=0,"",SUM(Q70:Z70)) | AB70: =IFERROR(IF(AA70="","",ROUND(AA70/AA$14*AB$14,2)),"") | AC70: =IFERROR(IF(AB70="","",ROUND(AB70*AC$14,2)),"") | AG70: =IFERROR(IF(AD70="","",ROUND(AD70/$AD$14*$AG$14,2)),"") | AH70: =IFERROR(IF(AE70="","",ROUND(AE70/$AE$14*$AH$14,2)),"") | AI70: =IFERROR(IF(AF70="","",ROUND(AF70/$AF$14*$AI$14,2)),"") | AJ70: =IF($AD$12=0,"",IF(OR(AG70<>"",AH70<>"",AI70<>""),(SUM(AG70:AI70)/SUM($AG$14:$AI$14))*$AJ$14,"")) | AK70: =IFERROR(IF(AJ70="","",ROUND(AJ70*$AK$14,2)),"") | AL70: =IF(AND(C70<>"",P70<>"",AC70<>"",$AD$12=0),SUM(P70,AC70),IF(AND(C70<>"",P70<>"",AC70<>"",AK70<>"",$D$12>0,$Q$12>0,$AD$12>0),SUM(P70,AC70,AK70),"")) | AM70: =IFERROR(_xlfn.XLOOKUP(AL70,HELPER!$C$7:$C$47,HELPER!$D$7:$D$47,,1),"")
B71: 4 | C71: =IFERROR(IF(OR($B$8="INCORRECT SHEET. Do not use this sheet to input data.",'INPUT DATA'!S14=""),"",'INPUT DATA'!S14),"") | N71: =IF(COUNT(D71:M71)=0,"",SUM(D71:M71)) | O71: =IFERROR(IF(N71="","",ROUND(N71/N$14*O$14,2)),"") | P71: =IFERROR(IF(O71="","",ROUND(O71*P$14,2)),"") | AA71: =IF(COUNT(Q71:Z71)=0,"",SUM(Q71:Z71)) | AB71: =IFERROR(IF(AA71="","",ROUND(AA71/AA$14*AB$14,2)),"") | AC71: =IFERROR(IF(AB71="","",ROUND(AB71*AC$14,2)),"") | AG71: =IFERROR(IF(AD71="","",ROUND(AD71/$AD$14*$AG$14,2)),"") | AH71: =IFERROR(IF(AE71="","",ROUND(AE71/$AE$14*$AH$14,2)),"") | AI71: =IFERROR(IF(AF71="","",ROUND(AF71/$AF$14*$AI$14,2)),"") | AJ71: =IF($AD$12=0,"",IF(OR(AG71<>"",AH71<>"",AI71<>""),(SUM(AG71:AI71)/SUM($AG$14:$AI$14))*$AJ$14,"")) | AK71: =IFERROR(IF(AJ71="","",ROUND(AJ71*$AK$14,2)),"") | AL71: =IF(AND(C71<>"",P71<>"",AC71<>"",$AD$12=0),SUM(P71,AC71),IF(AND(C71<>"",P71<>"",AC71<>"",AK71<>"",$D$12>0,$Q$12>0,$AD$12>0),SUM(P71,AC71,AK71),"")) | AM71: =IFERROR(_xlfn.XLOOKUP(AL71,HELPER!$C$7:$C$47,HELPER!$D$7:$D$47,,1),"")
B72: 5 | C72: =IFERROR(IF(OR($B$8="INCORRECT SHEET. Do not use this sheet to input data.",'INPUT DATA'!S15=""),"",'INPUT DATA'!S15),"") | N72: =IF(COUNT(D72:M72)=0,"",SUM(D72:M72)) | O72: =IFERROR(IF(N72="","",ROUND(N72/N$14*O$14,2)),"") | P72: =IFERROR(IF(O72="","",ROUND(O72*P$14,2)),"") | AA72: =IF(COUNT(Q72:Z72)=0,"",SUM(Q72:Z72)) | AB72: =IFERROR(IF(AA72="","",ROUND(AA72/AA$14*AB$14,2)),"") | AC72: =IFERROR(IF(AB72="","",ROUND(AB72*AC$14,2)),"") | AG72: =IFERROR(IF(AD72="","",ROUND(AD72/$AD$14*$AG$14,2)),"") | AH72: =IFERROR(IF(AE72="","",ROUND(AE72/$AE$14*$AH$14,2)),"") | AI72: =IFERROR(IF(AF72="","",ROUND(AF72/$AF$14*$AI$14,2)),"") | AJ72: =IF($AD$12=0,"",IF(OR(AG72<>"",AH72<>"",AI72<>""),(SUM(AG72:AI72)/SUM($AG$14:$AI$14))*$AJ$14,"")) | AK72: =IFERROR(IF(AJ72="","",ROUND(AJ72*$AK$14,2)),"") | AL72: =IF(AND(C72<>"",P72<>"",AC72<>"",$AD$12=0),SUM(P72,AC72),IF(AND(C72<>"",P72<>"",AC72<>"",AK72<>"",$D$12>0,$Q$12>0,$AD$12>0),SUM(P72,AC72,AK72),"")) | AM72: =IFERROR(_xlfn.XLOOKUP(AL72,HELPER!$C$7:$C$47,HELPER!$D$7:$D$47,,1),"")
B73: 6 | C73: =IFERROR(IF(OR($B$8="INCORRECT SHEET. Do not use this sheet to input data.",'INPUT DATA'!S16=""),"",'INPUT DATA'!S16),"") | N73: =IF(COUNT(D73:M73)=0,"",SUM(D73:M73)) | O73: =IFERROR(IF(N73="","",ROUND(N73/N$14*O$14,2)),"") | P73: =IFERROR(IF(O73="","",ROUND(O73*P$14,2)),"") | AA73: =IF(COUNT(Q73:Z73)=0,"",SUM(Q73:Z73)) | AB73: =IFERROR(IF(AA73="","",ROUND(AA73/AA$14*AB$14,2)),"") | AC73: =IFERROR(IF(AB73="","",ROUND(AB73*AC$14,2)),"") | AG73: =IFERROR(IF(AD73="","",ROUND(AD73/$AD$14*$AG$14,2)),"") | AH73: =IFERROR(IF(AE73="","",ROUND(AE73/$AE$14*$AH$14,2)),"") | AI73: =IFERROR(IF(AF73="","",ROUND(AF73/$AF$14*$AI$14,2)),"") | AJ73: =IF($AD$12=0,"",IF(OR(AG73<>"",AH73<>"",AI73<>""),(SUM(AG73:AI73)/SUM($AG$14:$AI$14))*$AJ$14,"")) | AK73: =IFERROR(IF(AJ73="","",ROUND(AJ73*$AK$14,2)),"") | AL73: =IF(AND(C73<>"",P73<>"",AC73<>"",$AD$12=0),SUM(P73,AC73),IF(AND(C73<>"",P73<>"",AC73<>"",AK73<>"",$D$12>0,$Q$12>0,$AD$12>0),SUM(P73,AC73,AK73),"")) | AM73: =IFERROR(_xlfn.XLOOKUP(AL73,HELPER!$C$7:$C$47,HELPER!$D$7:$D$47,,1),"")
B74: 7 | C74: =IFERROR(IF(OR($B$8="INCORRECT SHEET. Do not use this sheet to input data.",'INPUT DATA'!S17=""),"",'INPUT DATA'!S17),"") | N74: =IF(COUNT(D74:M74)=0,"",SUM(D74:M74)) | O74: =IFERROR(IF(N74="","",ROUND(N74/N$14*O$14,2)),"") | P74: =IFERROR(IF(O74="","",ROUND(O74*P$14,2)),"") | AA74: =IF(COUNT(Q74:Z74)=0,"",SUM(Q74:Z74)) | AB74: =IFERROR(IF(AA74="","",ROUND(AA74/AA$14*AB$14,2)),"") | AC74: =IFERROR(IF(AB74="","",ROUND(AB74*AC$14,2)),"") | AG74: =IFERROR(IF(AD74="","",ROUND(AD74/$AD$14*$AG$14,2)),"") | AH74: =IFERROR(IF(AE74="","",ROUND(AE74/$AE$14*$AH$14,2)),"") | AI74: =IFERROR(IF(AF74="","",ROUND(AF74/$AF$14*$AI$14,2)),"") | AJ74: =IF($AD$12=0,"",IF(OR(AG74<>"",AH74<>"",AI74<>""),(SUM(AG74:AI74)/SUM($AG$14:$AI$14))*$AJ$14,"")) | AK74: =IFERROR(IF(AJ74="","",ROUND(AJ74*$AK$14,2)),"") | AL74: =IF(AND(C74<>"",P74<>"",AC74<>"",$AD$12=0),SUM(P74,AC74),IF(AND(C74<>"",P74<>"",AC74<>"",AK74<>"",$D$12>0,$Q$12>0,$AD$12>0),SUM(P74,AC74,AK74),"")) | AM74: =IFERROR(_xlfn.XLOOKUP(AL74,HELPER!$C$7:$C$47,HELPER!$D$7:$D$47,,1),"")
B75: 8 | C75: =IFERROR(IF(OR($B$8="INCORRECT SHEET. Do not use this sheet to input data.",'INPUT DATA'!S18=""),"",'INPUT DATA'!S18),"") | N75: =IF(COUNT(D75:M75)=0,"",SUM(D75:M75)) | O75: =IFERROR(IF(N75="","",ROUND(N75/N$14*O$14,2)),"") | P75: =IFERROR(IF(O75="","",ROUND(O75*P$14,2)),"") | AA75: =IF(COUNT(Q75:Z75)=0,"",SUM(Q75:Z75)) | AB75: =IFERROR(IF(AA75="","",ROUND(AA75/AA$14*AB$14,2)),"") | AC75: =IFERROR(IF(AB75="","",ROUND(AB75*AC$14,2)),"") | AG75: =IFERROR(IF(AD75="","",ROUND(AD75/$AD$14*$AG$14,2)),"") | AH75: =IFERROR(IF(AE75="","",ROUND(AE75/$AE$14*$AH$14,2)),"") | AI75: =IFERROR(IF(AF75="","",ROUND(AF75/$AF$14*$AI$14,2)),"") | AJ75: =IF($AD$12=0,"",IF(OR(AG75<>"",AH75<>"",AI75<>""),(SUM(AG75:AI75)/SUM($AG$14:$AI$14))*$AJ$14,"")) | AK75: =IFERROR(IF(AJ75="","",ROUND(AJ75*$AK$14,2)),"") | AL75: =IF(AND(C75<>"",P75<>"",AC75<>"",$AD$12=0),SUM(P75,AC75),IF(AND(C75<>"",P75<>"",AC75<>"",AK75<>"",$D$12>0,$Q$12>0,$AD$12>0),SUM(P75,AC75,AK75),"")) | AM75: =IFERROR(_xlfn.XLOOKUP(AL75,HELPER!$C$7:$C$47,HELPER!$D$7:$D$47,,1),"")
B76: 9 | C76: =IFERROR(IF(OR($B$8="INCORRECT SHEET. Do not use this sheet to input data.",'INPUT DATA'!S19=""),"",'INPUT DATA'!S19),"") | N76: =IF(COUNT(D76:M76)=0,"",SUM(D76:M76)) | O76: =IFERROR(IF(N76="","",ROUND(N76/N$14*O$14,2)),"") | P76: =IFERROR(IF(O76="","",ROUND(O76*P$14,2)),"") | AA76: =IF(COUNT(Q76:Z76)=0,"",SUM(Q76:Z76)) | AB76: =IFERROR(IF(AA76="","",ROUND(AA76/AA$14*AB$14,2)),"") | AC76: =IFERROR(IF(AB76="","",ROUND(AB76*AC$14,2)),"") | AG76: =IFERROR(IF(AD76="","",ROUND(AD76/$AD$14*$AG$14,2)),"") | AH76: =IFERROR(IF(AE76="","",ROUND(AE76/$AE$14*$AH$14,2)),"") | AI76: =IFERROR(IF(AF76="","",ROUND(AF76/$AF$14*$AI$14,2)),"") | AJ76: =IF($AD$12=0,"",IF(OR(AG76<>"",AH76<>"",AI76<>""),(SUM(AG76:AI76)/SUM($AG$14:$AI$14))*$AJ$14,"")) | AK76: =IFERROR(IF(AJ76="","",ROUND(AJ76*$AK$14,2)),"") | AL76: =IF(AND(C76<>"",P76<>"",AC76<>"",$AD$12=0),SUM(P76,AC76),IF(AND(C76<>"",P76<>"",AC76<>"",AK76<>"",$D$12>0,$Q$12>0,$AD$12>0),SUM(P76,AC76,AK76),"")) | AM76: =IFERROR(_xlfn.XLOOKUP(AL76,HELPER!$C$7:$C$47,HELPER!$D$7:$D$47,,1),"")
B77: 10 | C77: =IFERROR(IF(OR($B$8="INCORRECT SHEET. Do not use this sheet to input data.",'INPUT DATA'!S20=""),"",'INPUT DATA'!S20),"") | N77: =IF(COUNT(D77:M77)=0,"",SUM(D77:M77)) | O77: =IFERROR(IF(N77="","",ROUND(N77/N$14*O$14,2)),"") | P77: =IFERROR(IF(O77="","",ROUND(O77*P$14,2)),"") | AA77: =IF(COUNT(Q77:Z77)=0,"",SUM(Q77:Z77)) | AB77: =IFERROR(IF(AA77="","",ROUND(AA77/AA$14*AB$14,2)),"") | AC77: =IFERROR(IF(AB77="","",ROUND(AB77*AC$14,2)),"") | AG77: =IFERROR(IF(AD77="","",ROUND(AD77/$AD$14*$AG$14,2)),"") | AH77: =IFERROR(IF(AE77="","",ROUND(AE77/$AE$14*$AH$14,2)),"") | AI77: =IFERROR(IF(AF77="","",ROUND(AF77/$AF$14*$AI$14,2)),"") | AJ77: =IF($AD$12=0,"",IF(OR(AG77<>"",AH77<>"",AI77<>""),(SUM(AG77:AI77)/SUM($AG$14:$AI$14))*$AJ$14,"")) | AK77: =IFERROR(IF(AJ77="","",ROUND(AJ77*$AK$14,2)),"") | AL77: =IF(AND(C77<>"",P77<>"",AC77<>"",$AD$12=0),SUM(P77,AC77),IF(AND(C77<>"",P77<>"",AC77<>"",AK77<>"",$D$12>0,$Q$12>0,$AD$12>0),SUM(P77,AC77,AK77),"")) | AM77: =IFERROR(_xlfn.XLOOKUP(AL77,HELPER!$C$7:$C$47,HELPER!$D$7:$D$47,,1),"")
B78: 11 | C78: =IFERROR(IF(OR($B$8="INCORRECT SHEET. Do not use this sheet to input data.",'INPUT DATA'!S21=""),"",'INPUT DATA'!S21),"") | N78: =IF(COUNT(D78:M78)=0,"",SUM(D78:M78)) | O78: =IFERROR(IF(N78="","",ROUND(N78/N$14*O$14,2)),"") | P78: =IFERROR(IF(O78="","",ROUND(O78*P$14,2)),"") | AA78: =IF(COUNT(Q78:Z78)=0,"",SUM(Q78:Z78)) | AB78: =IFERROR(IF(AA78="","",ROUND(AA78/AA$14*AB$14,2)),"") | AC78: =IFERROR(IF(AB78="","",ROUND(AB78*AC$14,2)),"") | AG78: =IFERROR(IF(AD78="","",ROUND(AD78/$AD$14*$AG$14,2)),"") | AH78: =IFERROR(IF(AE78="","",ROUND(AE78/$AE$14*$AH$14,2)),"") | AI78: =IFERROR(IF(AF78="","",ROUND(AF78/$AF$14*$AI$14,2)),"") | AJ78: =IF($AD$12=0,"",IF(OR(AG78<>"",AH78<>"",AI78<>""),(SUM(AG78:AI78)/SUM($AG$14:$AI$14))*$AJ$14,"")) | AK78: =IFERROR(IF(AJ78="","",ROUND(AJ78*$AK$14,2)),"") | AL78: =IF(AND(C78<>"",P78<>"",AC78<>"",$AD$12=0),SUM(P78,AC78),IF(AND(C78<>"",P78<>"",AC78<>"",AK78<>"",$D$12>0,$Q$12>0,$AD$12>0),SUM(P78,AC78,AK78),"")) | AM78: =IFERROR(_xlfn.XLOOKUP(AL78,HELPER!$C$7:$C$47,HELPER!$D$7:$D$47,,1),"")
B79: 12 | C79: =IFERROR(IF(OR($B$8="INCORRECT SHEET. Do not use this sheet to input data.",'INPUT DATA'!S22=""),"",'INPUT DATA'!S22),"") | N79: =IF(COUNT(D79:M79)=0,"",SUM(D79:M79)) | O79: =IFERROR(IF(N79="","",ROUND(N79/N$14*O$14,2)),"") | P79: =IFERROR(IF(O79="","",ROUND(O79*P$14,2)),"") | AA79: =IF(COUNT(Q79:Z79)=0,"",SUM(Q79:Z79)) | AB79: =IFERROR(IF(AA79="","",ROUND(AA79/AA$14*AB$14,2)),"") | AC79: =IFERROR(IF(AB79="","",ROUND(AB79*AC$14,2)),"") | AG79: =IFERROR(IF(AD79="","",ROUND(AD79/$AD$14*$AG$14,2)),"") | AH79: =IFERROR(IF(AE79="","",ROUND(AE79/$AE$14*$AH$14,2)),"") | AI79: =IFERROR(IF(AF79="","",ROUND(AF79/$AF$14*$AI$14,2)),"") | AJ79: =IF($AD$12=0,"",IF(OR(AG79<>"",AH79<>"",AI79<>""),(SUM(AG79:AI79)/SUM($AG$14:$AI$14))*$AJ$14,"")) | AK79: =IFERROR(IF(AJ79="","",ROUND(AJ79*$AK$14,2)),"") | AL79: =IF(AND(C79<>"",P79<>"",AC79<>"",$AD$12=0),SUM(P79,AC79),IF(AND(C79<>"",P79<>"",AC79<>"",AK79<>"",$D$12>0,$Q$12>0,$AD$12>0),SUM(P79,AC79,AK79),"")) | AM79: =IFERROR(_xlfn.XLOOKUP(AL79,HELPER!$C$7:$C$47,HELPER!$D$7:$D$47,,1),"")
...

Sheet Term 2
B2: Strengthened Senior High School Class Record
B3: (Pursuant to DepEd Order 15, series of 2026)
G6: REGION | H6: =UPPER('INPUT DATA'!F10) -> REGION IV-A | O6: DIVISION | P6: =UPPER('INPUT DATA'!F11) -> CALAMBA CITY | Z6: SCHOOL ID | AA6: =IF('INPUT DATA'!F13="","",'INPUT DATA'!F13) -> 301518
G7: SCHOOL NAME | H7: =UPPER('INPUT DATA'!F14) -> EDUARDO BARRETTO SR. INTEGRATED SCHOOL | Z7: SCHOOL YEAR | AA7: ='INPUT DATA'!F16&" "&'INPUT DATA'!G16 -> 2026 – 2027
B8: =IF(OR(HELPER!G23="2ND",HELPER!G23="1ST & 2ND",HELPER!G23="2ND & 3RD",HELPER!G23="1ST, 2ND, 3RD"),"","INCORRECT SHEET. Do not use this sheet to input data.")
B9: SECOND TERM | D9: GRADE LEVEL | H9: =IFERROR(IF(B8<>"INCORRECT SHEET. Do not use this sheet to input data.",'INPUT DATA'!F24,""),"") -> 11 | J9: SECTION | N9: =IFERROR(IF(B8<>"INCORRECT SHEET. Do not use this sheet to input data.",UPPER('INPUT DATA'!F25),""),"") -> MILKY WAY | Q9: SUBJECT | U9: =IFERROR(IF(B8<>"INCORRECT SHEET. Do not use this sheet to input data.",UPPER(HELPER!G10),""),"") -> GENERAL MATHEMATICS
D10: TEACHER | H10: =IFERROR(IF(B8<>"INCORRECT SHEET. Do not use this sheet to input data.",UPPER('INPUT DATA'!F22),""),"") -> KAREN P. GONZAGA | Q10: CLUSTER | U10: =IFERROR(IF(B8<>"INCORRECT SHEET. Do not use this sheet to input data.",UPPER(HELPER!G9),""),"") -> CORE | AH10: UNITS | AJ10: =IFERROR(IF(B8<>"INCORRECT SHEET. Do not use this sheet to input data.",HELPER!G27,""),"") -> 2 | AK10: / TERM | AL10: =IFERROR(IF(B8<>"INCORRECT SHEET. Do not use this sheet to input data.",HELPER!G28,""),"") -> 6 | AM10: / YEAR
D11: WRITTEN / ORAL WORKS (WWs) | Q11: PRODUCT / PERFORMANCE TASKS (PTs) | AD11: EXAMINATIONS (EXs) | AL11: INITIAL GRADE | AM11: TERM GRADE
D12: =IF($U$9<>"",IFERROR(_xlfn.IFNA(HELPER!G13/100,""),""),"") -> 0.2 | Q12: =IF($U$9<>"",IFERROR(_xlfn.IFNA(HELPER!G14/100,""),""),"") -> 0.5 | AD12: =IF($U$9<>"",IFERROR(_xlfn.IFNA(HELPER!G15/100,""),""),"") -> 0.3
D13: 1 | E13: 2 | F13: 3 | G13: 4 | H13: 5 | I13: 6 | J13: 7 | K13: 8 | L13: 9 | M13: 10 | N13: TOTAL | O13: PS | P13: WS | Q13: 1 | R13: 2 | S13: 3 | T13: 4 | U13: 5 | V13: 6 | W13: 7 | X13: 8 | Y13: 9 | Z13: 10 | AA13: TOTAL | AB13: PS | AC13: WS | AD13: ST 1 | AE13: ST 2 | AF13: TE | AG13: WS ST1 | AH13: WS ST2 | AI13: WS TE | AJ13: PS | AK13: WS
B14: HIGHEST POSSIBLE SCORE | N14: =SUM(D14:M14) -> 0 | O14: 100 | P14: =D12 -> 0.2 | AA14: =SUM(Q14:Z14) -> 0 | AB14: 100 | AC14: =Q12 -> 0.5 | AG14: =_xlfn.IFNA(HELPER!G17,"") -> 30 | AH14: =_xlfn.IFNA(HELPER!G18,"") -> 30 | AI14: =_xlfn.IFNA(HELPER!G19,"") -> 40 | AJ14: =IF(AD12=0,"",100) -> 100 | AK14: =AD12 -> 0.3
B15: LEARNERS' NAMES
B16: MALE
B17: 1 | C17: =IFERROR(IF(OR($B$8="INCORRECT SHEET. Do not use this sheet to input data.",'INPUT DATA'!O11=""),"",'INPUT DATA'!O11),"") -> CALICA, LJAY | N17: =IF(COUNT(D17:M17)=0,"",SUM(D17:M17)) | O17: =IFERROR(IF(N17="","",ROUND(N17/N$14*O$14,2)),"") | P17: =IFERROR(IF(O17="","",ROUND(O17*P$14,2)),"") | AA17: =IF(COUNT(Q17:Z17)=0,"",SUM(Q17:Z17)) | AB17: =IFERROR(IF(AA17="","",ROUND(AA17/AA$14*AB$14,2)),"") | AC17: =IFERROR(IF(AB17="","",ROUND(AB17*AC$14,2)),"") | AG17: =IFERROR(IF(AD17="","",ROUND(AD17/$AD$14*$AG$14,2)),"") | AH17: =IFERROR(IF(AE17="","",ROUND(AE17/$AE$14*$AH$14,2)),"") | AI17: =IFERROR(IF(AF17="","",ROUND(AF17/$AF$14*$AI$14,2)),"") | AJ17: =IF($AD$12=0,"",IF(OR(AG17<>"",AH17<>"",AI17<>""),(SUM(AG17:AI17)/SUM($AG$14:$AI$14))*$AJ$14,"")) | AK17: =IFERROR(IF(AJ17="","",ROUND(AJ17*$AK$14,2)),"") | AL17: =IF(AND(C17<>"",P17<>"",AC17<>"",$AD$12=0),SUM(P17,AC17),IF(AND(C17<>"",P17<>"",AC17<>"",AK17<>"",$D$12>0,$Q$12>0,$AD$12>0),SUM(P17,AC17,AK17),"")) | AM17: =IFERROR(_xlfn.XLOOKUP(AL17,HELPER!$C$7:$C$47,HELPER!$D$7:$D$47,,1),"")
B18: 2 | C18: =IFERROR(IF(OR($B$8="INCORRECT SHEET. Do not use this sheet to input data.",'INPUT DATA'!O12=""),"",'INPUT DATA'!O12),"") | N18: =IF(COUNT(D18:M18)=0,"",SUM(D18:M18)) | O18: =IFERROR(IF(N18="","",ROUND(N18/N$14*O$14,2)),"") | P18: =IFERROR(IF(O18="","",ROUND(O18*P$14,2)),"") | AA18: =IF(COUNT(Q18:Z18)=0,"",SUM(Q18:Z18)) | AB18: =IFERROR(IF(AA18="","",ROUND(AA18/AA$14*AB$14,2)),"") | AC18: =IFERROR(IF(AB18="","",ROUND(AB18*AC$14,2)),"") | AG18: =IFERROR(IF(AD18="","",ROUND(AD18/$AD$14*$AG$14,2)),"") | AH18: =IFERROR(IF(AE18="","",ROUND(AE18/$AE$14*$AH$14,2)),"") | AI18: =IFERROR(IF(AF18="","",ROUND(AF18/$AF$14*$AI$14,2)),"") | AJ18: =IF($AD$12=0,"",IF(OR(AG18<>"",AH18<>"",AI18<>""),(SUM(AG18:AI18)/SUM($AG$14:$AI$14))*$AJ$14,"")) | AK18: =IFERROR(IF(AJ18="","",ROUND(AJ18*$AK$14,2)),"") | AL18: =IF(AND(C18<>"",P18<>"",AC18<>"",$AD$12=0),SUM(P18,AC18),IF(AND(C18<>"",P18<>"",AC18<>"",AK18<>"",$D$12>0,$Q$12>0,$AD$12>0),SUM(P18,AC18,AK18),"")) | AM18: =IFERROR(_xlfn.XLOOKUP(AL18,HELPER!$C$7:$C$47,HELPER!$D$7:$D$47,,1),"")
B19: 3 | C19: =IFERROR(IF(OR($B$8="INCORRECT SHEET. Do not use this sheet to input data.",'INPUT DATA'!O13=""),"",'INPUT DATA'!O13),"") | N19: =IF(COUNT(D19:M19)=0,"",SUM(D19:M19)) | O19: =IFERROR(IF(N19="","",ROUND(N19/N$14*O$14,2)),"") | P19: =IFERROR(IF(O19="","",ROUND(O19*P$14,2)),"") | AA19: =IF(COUNT(Q19:Z19)=0,"",SUM(Q19:Z19)) | AB19: =IFERROR(IF(AA19="","",ROUND(AA19/AA$14*AB$14,2)),"") | AC19: =IFERROR(IF(AB19="","",ROUND(AB19*AC$14,2)),"") | AG19: =IFERROR(IF(AD19="","",ROUND(AD19/$AD$14*$AG$14,2)),"") | AH19: =IFERROR(IF(AE19="","",ROUND(AE19/$AE$14*$AH$14,2)),"") | AI19: =IFERROR(IF(AF19="","",ROUND(AF19/$AF$14*$AI$14,2)),"") | AJ19: =IF($AD$12=0,"",IF(OR(AG19<>"",AH19<>"",AI19<>""),(SUM(AG19:AI19)/SUM($AG$14:$AI$14))*$AJ$14,"")) | AK19: =IFERROR(IF(AJ19="","",ROUND(AJ19*$AK$14,2)),"") | AL19: =IF(AND(C19<>"",P19<>"",AC19<>"",$AD$12=0),SUM(P19,AC19),IF(AND(C19<>"",P19<>"",AC19<>"",AK19<>"",$D$12>0,$Q$12>0,$AD$12>0),SUM(P19,AC19,AK19),"")) | AM19: =IFERROR(_xlfn.XLOOKUP(AL19,HELPER!$C$7:$C$47,HELPER!$D$7:$D$47,,1),"")
B20: 4 | C20: =IFERROR(IF(OR($B$8="INCORRECT SHEET. Do not use this sheet to input data.",'INPUT DATA'!O14=""),"",'INPUT DATA'!O14),"") | N20: =IF(COUNT(D20:M20)=0,"",SUM(D20:M20)) | O20: =IFERROR(IF(N20="","",ROUND(N20/N$14*O$14,2)),"") | P20: =IFERROR(IF(O20="","",ROUND(O20*P$14,2)),"") | AA20: =IF(COUNT(Q20:Z20)=0,"",SUM(Q20:Z20)) | AB20: =IFERROR(IF(AA20="","",ROUND(AA20/AA$14*AB$14,2)),"") | AC20: =IFERROR(IF(AB20="","",ROUND(AB20*AC$14,2)),"") | AG20: =IFERROR(IF(AD20="","",ROUND(AD20/$AD$14*$AG$14,2)),"") | AH20: =IFERROR(IF(AE20="","",ROUND(AE20/$AE$14*$AH$14,2)),"") | AI20: =IFERROR(IF(AF20="","",ROUND(AF20/$AF$14*$AI$14,2)),"") | AJ20: =IF($AD$12=0,"",IF(OR(AG20<>"",AH20<>"",AI20<>""),(SUM(AG20:AI20)/SUM($AG$14:$AI$14))*$AJ$14,"")) | AK20: =IFERROR(IF(AJ20="","",ROUND(AJ20*$AK$14,2)),"") | AL20: =IF(AND(C20<>"",P20<>"",AC20<>"",$AD$12=0),SUM(P20,AC20),IF(AND(C20<>"",P20<>"",AC20<>"",AK20<>"",$D$12>0,$Q$12>0,$AD$12>0),SUM(P20,AC20,AK20),"")) | AM20: =IFERROR(_xlfn.XLOOKUP(AL20,HELPER!$C$7:$C$47,HELPER!$D$7:$D$47,,1),"")
B21: 5 | C21: =IFERROR(IF(OR($B$8="INCORRECT SHEET. Do not use this sheet to input data.",'INPUT DATA'!O15=""),"",'INPUT DATA'!O15),"") | N21: =IF(COUNT(D21:M21)=0,"",SUM(D21:M21)) | O21: =IFERROR(IF(N21="","",ROUND(N21/N$14*O$14,2)),"") | P21: =IFERROR(IF(O21="","",ROUND(O21*P$14,2)),"") | AA21: =IF(COUNT(Q21:Z21)=0,"",SUM(Q21:Z21)) | AB21: =IFERROR(IF(AA21="","",ROUND(AA21/AA$14*AB$14,2)),"") | AC21: =IFERROR(IF(AB21="","",ROUND(AB21*AC$14,2)),"") | AG21: =IFERROR(IF(AD21="","",ROUND(AD21/$AD$14*$AG$14,2)),"") | AH21: =IFERROR(IF(AE21="","",ROUND(AE21/$AE$14*$AH$14,2)),"") | AI21: =IFERROR(IF(AF21="","",ROUND(AF21/$AF$14*$AI$14,2)),"") | AJ21: =IF($AD$12=0,"",IF(OR(AG21<>"",AH21<>"",AI21<>""),(SUM(AG21:AI21)/SUM($AG$14:$AI$14))*$AJ$14,"")) | AK21: =IFERROR(IF(AJ21="","",ROUND(AJ21*$AK$14,2)),"") | AL21: =IF(AND(C21<>"",P21<>"",AC21<>"",$AD$12=0),SUM(P21,AC21),IF(AND(C21<>"",P21<>"",AC21<>"",AK21<>"",$D$12>0,$Q$12>0,$AD$12>0),SUM(P21,AC21,AK21),"")) | AM21: =IFERROR(_xlfn.XLOOKUP(AL21,HELPER!$C$7:$C$47,HELPER!$D$7:$D$47,,1),"")
B22: 6 | C22: =IFERROR(IF(OR($B$8="INCORRECT SHEET. Do not use this sheet to input data.",'INPUT DATA'!O16=""),"",'INPUT DATA'!O16),"") | N22: =IF(COUNT(D22:M22)=0,"",SUM(D22:M22)) | O22: =IFERROR(IF(N22="","",ROUND(N22/N$14*O$14,2)),"") | P22: =IFERROR(IF(O22="","",ROUND(O22*P$14,2)),"") | AA22: =IF(COUNT(Q22:Z22)=0,"",SUM(Q22:Z22)) | AB22: =IFERROR(IF(AA22="","",ROUND(AA22/AA$14*AB$14,2)),"") | AC22: =IFERROR(IF(AB22="","",ROUND(AB22*AC$14,2)),"") | AG22: =IFERROR(IF(AD22="","",ROUND(AD22/$AD$14*$AG$14,2)),"") | AH22: =IFERROR(IF(AE22="","",ROUND(AE22/$AE$14*$AH$14,2)),"") | AI22: =IFERROR(IF(AF22="","",ROUND(AF22/$AF$14*$AI$14,2)),"") | AJ22: =IF($AD$12=0,"",IF(OR(AG22<>"",AH22<>"",AI22<>""),(SUM(AG22:AI22)/SUM($AG$14:$AI$14))*$AJ$14,"")) | AK22: =IFERROR(IF(AJ22="","",ROUND(AJ22*$AK$14,2)),"") | AL22: =IF(AND(C22<>"",P22<>"",AC22<>"",$AD$12=0),SUM(P22,AC22),IF(AND(C22<>"",P22<>"",AC22<>"",AK22<>"",$D$12>0,$Q$12>0,$AD$12>0),SUM(P22,AC22,AK22),"")) | AM22: =IFERROR(_xlfn.XLOOKUP(AL22,HELPER!$C$7:$C$47,HELPER!$D$7:$D$47,,1),"")
B23: 7 | C23: =IFERROR(IF(OR($B$8="INCORRECT SHEET. Do not use this sheet to input data.",'INPUT DATA'!O17=""),"",'INPUT DATA'!O17),"") | N23: =IF(COUNT(D23:M23)=0,"",SUM(D23:M23)) | O23: =IFERROR(IF(N23="","",ROUND(N23/N$14*O$14,2)),"") | P23: =IFERROR(IF(O23="","",ROUND(O23*P$14,2)),"") | AA23: =IF(COUNT(Q23:Z23)=0,"",SUM(Q23:Z23)) | AB23: =IFERROR(IF(AA23="","",ROUND(AA23/AA$14*AB$14,2)),"") | AC23: =IFERROR(IF(AB23="","",ROUND(AB23*AC$14,2)),"") | AG23: =IFERROR(IF(AD23="","",ROUND(AD23/$AD$14*$AG$14,2)),"") | AH23: =IFERROR(IF(AE23="","",ROUND(AE23/$AE$14*$AH$14,2)),"") | AI23: =IFERROR(IF(AF23="","",ROUND(AF23/$AF$14*$AI$14,2)),"") | AJ23: =IF($AD$12=0,"",IF(OR(AG23<>"",AH23<>"",AI23<>""),(SUM(AG23:AI23)/SUM($AG$14:$AI$14))*$AJ$14,"")) | AK23: =IFERROR(IF(AJ23="","",ROUND(AJ23*$AK$14,2)),"") | AL23: =IF(AND(C23<>"",P23<>"",AC23<>"",$AD$12=0),SUM(P23,AC23),IF(AND(C23<>"",P23<>"",AC23<>"",AK23<>"",$D$12>0,$Q$12>0,$AD$12>0),SUM(P23,AC23,AK23),"")) | AM23: =IFERROR(_xlfn.XLOOKUP(AL23,HELPER!$C$7:$C$47,HELPER!$D$7:$D$47,,1),"")
B24: 8 | C24: =IFERROR(IF(OR($B$8="INCORRECT SHEET. Do not use this sheet to input data.",'INPUT DATA'!O18=""),"",'INPUT DATA'!O18),"") | N24: =IF(COUNT(D24:M24)=0,"",SUM(D24:M24)) | O24: =IFERROR(IF(N24="","",ROUND(N24/N$14*O$14,2)),"") | P24: =IFERROR(IF(O24="","",ROUND(O24*P$14,2)),"") | AA24: =IF(COUNT(Q24:Z24)=0,"",SUM(Q24:Z24)) | AB24: =IFERROR(IF(AA24="","",ROUND(AA24/AA$14*AB$14,2)),"") | AC24: =IFERROR(IF(AB24="","",ROUND(AB24*AC$14,2)),"") | AG24: =IFERROR(IF(AD24="","",ROUND(AD24/$AD$14*$AG$14,2)),"") | AH24: =IFERROR(IF(AE24="","",ROUND(AE24/$AE$14*$AH$14,2)),"") | AI24: =IFERROR(IF(AF24="","",ROUND(AF24/$AF$14*$AI$14,2)),"") | AJ24: =IF($AD$12=0,"",IF(OR(AG24<>"",AH24<>"",AI24<>""),(SUM(AG24:AI24)/SUM($AG$14:$AI$14))*$AJ$14,"")) | AK24: =IFERROR(IF(AJ24="","",ROUND(AJ24*$AK$14,2)),"") | AL24: =IF(AND(C24<>"",P24<>"",AC24<>"",$AD$12=0),SUM(P24,AC24),IF(AND(C24<>"",P24<>"",AC24<>"",AK24<>"",$D$12>0,$Q$12>0,$AD$12>0),SUM(P24,AC24,AK24),"")) | AM24: =IFERROR(_xlfn.XLOOKUP(AL24,HELPER!$C$7:$C$47,HELPER!$D$7:$D$47,,1),"")
B25: 9 | C25: =IFERROR(IF(OR($B$8="INCORRECT SHEET. Do not use this sheet to input data.",'INPUT DATA'!O19=""),"",'INPUT DATA'!O19),"") | N25: =IF(COUNT(D25:M25)=0,"",SUM(D25:M25)) | O25: =IFERROR(IF(N25="","",ROUND(N25/N$14*O$14,2)),"") | P25: =IFERROR(IF(O25="","",ROUND(O25*P$14,2)),"") | AA25: =IF(COUNT(Q25:Z25)=0,"",SUM(Q25:Z25)) | AB25: =IFERROR(IF(AA25="","",ROUND(AA25/AA$14*AB$14,2)),"") | AC25: =IFERROR(IF(AB25="","",ROUND(AB25*AC$14,2)),"") | AG25: =IFERROR(IF(AD25="","",ROUND(AD25/$AD$14*$AG$14,2)),"") | AH25: =IFERROR(IF(AE25="","",ROUND(AE25/$AE$14*$AH$14,2)),"") | AI25: =IFERROR(IF(AF25="","",ROUND(AF25/$AF$14*$AI$14,2)),"") | AJ25: =IF($AD$12=0,"",IF(OR(AG25<>"",AH25<>"",AI25<>""),(SUM(AG25:AI25)/SUM($AG$14:$AI$14))*$AJ$14,"")) | AK25: =IFERROR(IF(AJ25="","",ROUND(AJ25*$AK$14,2)),"") | AL25: =IF(AND(C25<>"",P25<>"",AC25<>"",$AD$12=0),SUM(P25,AC25),IF(AND(C25<>"",P25<>"",AC25<>"",AK25<>"",$D$12>0,$Q$12>0,$AD$12>0),SUM(P25,AC25,AK25),"")) | AM25: =IFERROR(_xlfn.XLOOKUP(AL25,HELPER!$C$7:$C$47,HELPER!$D$7:$D$47,,1),"")
B26: 10 | C26: =IFERROR(IF(OR($B$8="INCORRECT SHEET. Do not use this sheet to input data.",'INPUT DATA'!O20=""),"",'INPUT DATA'!O20),"") | N26: =IF(COUNT(D26:M26)=0,"",SUM(D26:M26)) | O26: =IFERROR(IF(N26="","",ROUND(N26/N$14*O$14,2)),"") | P26: =IFERROR(IF(O26="","",ROUND(O26*P$14,2)),"") | AA26: =IF(COUNT(Q26:Z26)=0,"",SUM(Q26:Z26)) | AB26: =IFERROR(IF(AA26="","",ROUND(AA26/AA$14*AB$14,2)),"") | AC26: =IFERROR(IF(AB26="","",ROUND(AB26*AC$14,2)),"") | AG26: =IFERROR(IF(AD26="","",ROUND(AD26/$AD$14*$AG$14,2)),"") | AH26: =IFERROR(IF(AE26="","",ROUND(AE26/$AE$14*$AH$14,2)),"") | AI26: =IFERROR(IF(AF26="","",ROUND(AF26/$AF$14*$AI$14,2)),"") | AJ26: =IF($AD$12=0,"",IF(OR(AG26<>"",AH26<>"",AI26<>""),(SUM(AG26:AI26)/SUM($AG$14:$AI$14))*$AJ$14,"")) | AK26: =IFERROR(IF(AJ26="","",ROUND(AJ26*$AK$14,2)),"") | AL26: =IF(AND(C26<>"",P26<>"",AC26<>"",$AD$12=0),SUM(P26,AC26),IF(AND(C26<>"",P26<>"",AC26<>"",AK26<>"",$D$12>0,$Q$12>0,$AD$12>0),SUM(P26,AC26,AK26),"")) | AM26: =IFERROR(_xlfn.XLOOKUP(AL26,HELPER!$C$7:$C$47,HELPER!$D$7:$D$47,,1),"")
B27: 11 | C27: =IFERROR(IF(OR($B$8="INCORRECT SHEET. Do not use this sheet to input data.",'INPUT DATA'!O21=""),"",'INPUT DATA'!O21),"") | N27: =IF(COUNT(D27:M27)=0,"",SUM(D27:M27)) | O27: =IFERROR(IF(N27="","",ROUND(N27/N$14*O$14,2)),"") | P27: =IFERROR(IF(O27="","",ROUND(O27*P$14,2)),"") | AA27: =IF(COUNT(Q27:Z27)=0,"",SUM(Q27:Z27)) | AB27: =IFERROR(IF(AA27="","",ROUND(AA27/AA$14*AB$14,2)),"") | AC27: =IFERROR(IF(AB27="","",ROUND(AB27*AC$14,2)),"") | AG27: =IFERROR(IF(AD27="","",ROUND(AD27/$AD$14*$AG$14,2)),"") | AH27: =IFERROR(IF(AE27="","",ROUND(AE27/$AE$14*$AH$14,2)),"") | AI27: =IFERROR(IF(AF27="","",ROUND(AF27/$AF$14*$AI$14,2)),"") | AJ27: =IF($AD$12=0,"",IF(OR(AG27<>"",AH27<>"",AI27<>""),(SUM(AG27:AI27)/SUM($AG$14:$AI$14))*$AJ$14,"")) | AK27: =IFERROR(IF(AJ27="","",ROUND(AJ27*$AK$14,2)),"") | AL27: =IF(AND(C27<>"",P27<>"",AC27<>"",$AD$12=0),SUM(P27,AC27),IF(AND(C27<>"",P27<>"",AC27<>"",AK27<>"",$D$12>0,$Q$12>0,$AD$12>0),SUM(P27,AC27,AK27),"")) | AM27: =IFERROR(_xlfn.XLOOKUP(AL27,HELPER!$C$7:$C$47,HELPER!$D$7:$D$47,,1),"")
B28: 12 | C28: =IFERROR(IF(OR($B$8="INCORRECT SHEET. Do not use this sheet to input data.",'INPUT DATA'!O22=""),"",'INPUT DATA'!O22),"") | N28: =IF(COUNT(D28:M28)=0,"",SUM(D28:M28)) | O28: =IFERROR(IF(N28="","",ROUND(N28/N$14*O$14,2)),"") | P28: =IFERROR(IF(O28="","",ROUND(O28*P$14,2)),"") | AA28: =IF(COUNT(Q28:Z28)=0,"",SUM(Q28:Z28)) | AB28: =IFERROR(IF(AA28="","",ROUND(AA28/AA$14*AB$14,2)),"") | AC28: =IFERROR(IF(AB28="","",ROUND(AB28*AC$14,2)),"") | AG28: =IFERROR(IF(AD28="","",ROUND(AD28/$AD$14*$AG$14,2)),"") | AH28: =IFERROR(IF(AE28="","",ROUND(AE28/$AE$14*$AH$14,2)),"") | AI28: =IFERROR(IF(AF28="","",ROUND(AF28/$AF$14*$AI$14,2)),"") | AJ28: =IF($AD$12=0,"",IF(OR(AG28<>"",AH28<>"",AI28<>""),(SUM(AG28:AI28)/SUM($AG$14:$AI$14))*$AJ$14,"")) | AK28: =IFERROR(IF(AJ28="","",ROUND(AJ28*$AK$14,2)),"") | AL28: =IF(AND(C28<>"",P28<>"",AC28<>"",$AD$12=0),SUM(P28,AC28),IF(AND(C28<>"",P28<>"",AC28<>"",AK28<>"",$D$12>0,$Q$12>0,$AD$12>0),SUM(P28,AC28,AK28),"")) | AM28: =IFERROR(_xlfn.XLOOKUP(AL28,HELPER!$C$7:$C$47,HELPER!$D$7:$D$47,,1),"")
... B66: 50 | C66: =IFERROR(IF(OR($B$8="INCORRECT SHEET. Do not use this sheet to input data.",'INPUT DATA'!O60=""),"",'INPUT DATA'!O60),"") | N66: =IF(COUNT(D66:M66)=0,"",SUM(D66:M66)) | O66: =IFERROR(IF(N66="","",ROUND(N66/N$14*O$14,2)),"") | P66: =IFERROR(IF(O66="","",ROUND(O66*P$14,2)),"") | AA66: =IF(COUNT(Q66:Z66)=0,"",SUM(Q66:Z66)) | AB66: =IFERROR(IF(AA66="","",ROUND(AA66/AA$14*AB$14,2)),"") | AC66: =IFERROR(IF(AB66="","",ROUND(AB66*AC$14,2)),"") | AG66: =IFERROR(IF(AD66="","",ROUND(AD66/$AD$14*$AG$14,2)),"") | AH66: =IFERROR(IF(AE66="","",ROUND(AE66/$AE$14*$AH$14,2)),"") | AI66: =IFERROR(IF(AF66="","",ROUND(AF66/$AF$14*$AI$14,2)),"") | AJ66: =IF($AD$12=0,"",IF(OR(AG66<>"",AH66<>"",AI66<>""),(SUM(AG66:AI66)/SUM($AG$14:$AI$14))*$AJ$14,"")) | AK66: =IFERROR(IF(AJ66="","",ROUND(AJ66*$AK$14,2)),"") | AL66: =IF(AND(C66<>"",P66<>"",AC66<>"",$AD$12=0),SUM(P66,AC66),IF(AND(C66<>"",P66<>"",AC66<>"",AK66<>"",$D$12>0,$Q$12>0,$AD$12>0),SUM(P66,AC66,AK66),"")) | AM66: =IFERROR(_xlfn.XLOOKUP(AL66,HELPER!$C$7:$C$47,HELPER!$D$7:$D$47,,1),"")
B67: FEMALE
B68: 1 | C68: =IFERROR(IF(OR($B$8="INCORRECT SHEET. Do not use this sheet to input data.",'INPUT DATA'!S11=""),"",'INPUT DATA'!S11),"") | N68: =IF(COUNT(D68:M68)=0,"",SUM(D68:M68)) | O68: =IFERROR(IF(N68="","",ROUND(N68/N$14*O$14,2)),"") | P68: =IFERROR(IF(O68="","",ROUND(O68*P$14,2)),"") | AA68: =IF(COUNT(Q68:Z68)=0,"",SUM(Q68:Z68)) | AB68: =IFERROR(IF(AA68="","",ROUND(AA68/AA$14*AB$14,2)),"") | AC68: =IFERROR(IF(AB68="","",ROUND(AB68*AC$14,2)),"") | AG68: =IFERROR(IF(AD68="","",ROUND(AD68/$AD$14*$AG$14,2)),"") | AH68: =IFERROR(IF(AE68="","",ROUND(AE68/$AE$14*$AH$14,2)),"") | AI68: =IFERROR(IF(AF68="","",ROUND(AF68/$AF$14*$AI$14,2)),"") | AJ68: =IF($AD$12=0,"",IF(OR(AG68<>"",AH68<>"",AI68<>""),(SUM(AG68:AI68)/SUM($AG$14:$AI$14))*$AJ$14,"")) | AK68: =IFERROR(IF(AJ68="","",ROUND(AJ68*$AK$14,2)),"") | AL68: =IF(AND(C68<>"",P68<>"",AC68<>"",$AD$12=0),SUM(P68,AC68),IF(AND(C68<>"",P68<>"",AC68<>"",AK68<>"",$D$12>0,$Q$12>0,$AD$12>0),SUM(P68,AC68,AK68),"")) | AM68: =IFERROR(_xlfn.XLOOKUP(AL68,HELPER!$C$7:$C$47,HELPER!$D$7:$D$47,,1),"")
B69: 2 | C69: =IFERROR(IF(OR($B$8="INCORRECT SHEET. Do not use this sheet to input data.",'INPUT DATA'!S12=""),"",'INPUT DATA'!S12),"") | N69: =IF(COUNT(D69:M69)=0,"",SUM(D69:M69)) | O69: =IFERROR(IF(N69="","",ROUND(N69/N$14*O$14,2)),"") | P69: =IFERROR(IF(O69="","",ROUND(O69*P$14,2)),"") | AA69: =IF(COUNT(Q69:Z69)=0,"",SUM(Q69:Z69)) | AB69: =IFERROR(IF(AA69="","",ROUND(AA69/AA$14*AB$14,2)),"") | AC69: =IFERROR(IF(AB69="","",ROUND(AB69*AC$14,2)),"") | AG69: =IFERROR(IF(AD69="","",ROUND(AD69/$AD$14*$AG$14,2)),"") | AH69: =IFERROR(IF(AE69="","",ROUND(AE69/$AE$14*$AH$14,2)),"") | AI69: =IFERROR(IF(AF69="","",ROUND(AF69/$AF$14*$AI$14,2)),"") | AJ69: =IF($AD$12=0,"",IF(OR(AG69<>"",AH69<>"",AI69<>""),(SUM(AG69:AI69)/SUM($AG$14:$AI$14))*$AJ$14,"")) | AK69: =IFERROR(IF(AJ69="","",ROUND(AJ69*$AK$14,2)),"") | AL69: =IF(AND(C69<>"",P69<>"",AC69<>"",$AD$12=0),SUM(P69,AC69),IF(AND(C69<>"",P69<>"",AC69<>"",AK69<>"",$D$12>0,$Q$12>0,$AD$12>0),SUM(P69,AC69,AK69),"")) | AM69: =IFERROR(_xlfn.XLOOKUP(AL69,HELPER!$C$7:$C$47,HELPER!$D$7:$D$47,,1),"")
B70: 3 | C70: =IFERROR(IF(OR($B$8="INCORRECT SHEET. Do not use this sheet to input data.",'INPUT DATA'!S13=""),"",'INPUT DATA'!S13),"") | N70: =IF(COUNT(D70:M70)=0,"",SUM(D70:M70)) | O70: =IFERROR(IF(N70="","",ROUND(N70/N$14*O$14,2)),"") | P70: =IFERROR(IF(O70="","",ROUND(O70*P$14,2)),"") | AA70: =IF(COUNT(Q70:Z70)=0,"",SUM(Q70:Z70)) | AB70: =IFERROR(IF(AA70="","",ROUND(AA70/AA$14*AB$14,2)),"") | AC70: =IFERROR(IF(AB70="","",ROUND(AB70*AC$14,2)),"") | AG70: =IFERROR(IF(AD70="","",ROUND(AD70/$AD$14*$AG$14,2)),"") | AH70: =IFERROR(IF(AE70="","",ROUND(AE70/$AE$14*$AH$14,2)),"") | AI70: =IFERROR(IF(AF70="","",ROUND(AF70/$AF$14*$AI$14,2)),"") | AJ70: =IF($AD$12=0,"",IF(OR(AG70<>"",AH70<>"",AI70<>""),(SUM(AG70:AI70)/SUM($AG$14:$AI$14))*$AJ$14,"")) | AK70: =IFERROR(IF(AJ70="","",ROUND(AJ70*$AK$14,2)),"") | AL70: =IF(AND(C70<>"",P70<>"",AC70<>"",$AD$12=0),SUM(P70,AC70),IF(AND(C70<>"",P70<>"",AC70<>"",AK70<>"",$D$12>0,$Q$12>0,$AD$12>0),SUM(P70,AC70,AK70),"")) | AM70: =IFERROR(_xlfn.XLOOKUP(AL70,HELPER!$C$7:$C$47,HELPER!$D$7:$D$47,,1),"")
B71: 4 | C71: =IFERROR(IF(OR($B$8="INCORRECT SHEET. Do not use this sheet to input data.",'INPUT DATA'!S14=""),"",'INPUT DATA'!S14),"") | N71: =IF(COUNT(D71:M71)=0,"",SUM(D71:M71)) | O71: =IFERROR(IF(N71="","",ROUND(N71/N$14*O$14,2)),"") | P71: =IFERROR(IF(O71="","",ROUND(O71*P$14,2)),"") | AA71: =IF(COUNT(Q71:Z71)=0,"",SUM(Q71:Z71)) | AB71: =IFERROR(IF(AA71="","",ROUND(AA71/AA$14*AB$14,2)),"") | AC71: =IFERROR(IF(AB71="","",ROUND(AB71*AC$14,2)),"") | AG71: =IFERROR(IF(AD71="","",ROUND(AD71/$AD$14*$AG$14,2)),"") | AH71: =IFERROR(IF(AE71="","",ROUND(AE71/$AE$14*$AH$14,2)),"") | AI71: =IFERROR(IF(AF71="","",ROUND(AF71/$AF$14*$AI$14,2)),"") | AJ71: =IF($AD$12=0,"",IF(OR(AG71<>"",AH71<>"",AI71<>""),(SUM(AG71:AI71)/SUM($AG$14:$AI$14))*$AJ$14,"")) | AK71: =IFERROR(IF(AJ71="","",ROUND(AJ71*$AK$14,2)),"") | AL71: =IF(AND(C71<>"",P71<>"",AC71<>"",$AD$12=0),SUM(P71,AC71),IF(AND(C71<>"",P71<>"",AC71<>"",AK71<>"",$D$12>0,$Q$12>0,$AD$12>0),SUM(P71,AC71,AK71),"")) | AM71: =IFERROR(_xlfn.XLOOKUP(AL71,HELPER!$C$7:$C$47,HELPER!$D$7:$D$47,,1),"")
B72: 5 | C72: =IFERROR(IF(OR($B$8="INCORRECT SHEET. Do not use this sheet to input data.",'INPUT DATA'!S15=""),"",'INPUT DATA'!S15),"") | N72: =IF(COUNT(D72:M72)=0,"",SUM(D72:M72)) | O72: =IFERROR(IF(N72="","",ROUND(N72/N$14*O$14,2)),"") | P72: =IFERROR(IF(O72="","",ROUND(O72*P$14,2)),"") | AA72: =IF(COUNT(Q72:Z72)=0,"",SUM(Q72:Z72)) | AB72: =IFERROR(IF(AA72="","",ROUND(AA72/AA$14*AB$14,2)),"") | AC72: =IFERROR(IF(AB72="","",ROUND(AB72*AC$14,2)),"") | AG72: =IFERROR(IF(AD72="","",ROUND(AD72/$AD$14*$AG$14,2)),"") | AH72: =IFERROR(IF(AE72="","",ROUND(AE72/$AE$14*$AH$14,2)),"") | AI72: =IFERROR(IF(AF72="","",ROUND(AF72/$AF$14*$AI$14,2)),"") | AJ72: =IF($AD$12=0,"",IF(OR(AG72<>"",AH72<>"",AI72<>""),(SUM(AG72:AI72)/SUM($AG$14:$AI$14))*$AJ$14,"")) | AK72: =IFERROR(IF(AJ72="","",ROUND(AJ72*$AK$14,2)),"") | AL72: =IF(AND(C72<>"",P72<>"",AC72<>"",$AD$12=0),SUM(P72,AC72),IF(AND(C72<>"",P72<>"",AC72<>"",AK72<>"",$D$12>0,$Q$12>0,$AD$12>0),SUM(P72,AC72,AK72),"")) | AM72: =IFERROR(_xlfn.XLOOKUP(AL72,HELPER!$C$7:$C$47,HELPER!$D$7:$D$47,,1),"")
